Workbook

Sheet ПФ2026
C1: -1
B3: Статьи Затрат | C3: 1 квартал 2026г. | I3: 2 квартал 2026г. | O3: 3 квартал 2026г. | U3: 4 квартал 2026г. | AA3: Общий Итог
C4: Январь | E4: Февраль | G4: Март | I4: Апрель | K4: Май | M4: Июнь | O4: Июль | Q4: Август | S4: Сентябрь | U4: Октябрь | W4: Ноябрь | Y4: Декабрь
C5: План | D5: Факт | E5: План | F5: Факт | G5: План | H5: Факт | I5: План | J5: Факт | K5: План | L5: Факт | M5: План | N5: Факт | O5: План | P5: Факт | Q5: План | R5: Факт | S5: План | T5: Факт | U5: План | V5: Факт | W5: План | X5: Факт | Y5: План | Z5: Факт | AA5: План | AB5: Факт | AC5: Откл %
B6: Маржинальная прибыль | C6: =C7+C13 -> 1.3314047e+08 | D6: =D7+D13 -> 1.6298824e+08 | E6: =E7+E13 -> 1.4464568e+08 | F6: =F7+F13 -> 1.7509059e+08 | G6: =G7+G13 -> 2.2596815e+08 | H6: =H7+H13 -> 2.3707425e+08 | I6: =I7+I13 -> 3.5249091e+08 | J6: =J7+J13 -> 3.5113252e+08 | ... Z6: =Z7+Z13 -> 0 | AA6: =C6+E6+G6+I6+K6+M6+O6+Q6+S6+U6+W6+Y6 -> 3.4235606e+09 | AB6: =D6+F6+H6+J6+L6+N6+P6+R6+T6+V6+X6+Z6 -> 1.8698216e+09 | AC6: =IFERROR(AB6/AA6,0) -> 0.54616284
B7: Доходы | C7: =SUM(C8,C10) -> 2.237922e+08 | D7: =SUM(D8,D10) -> 2.8666775e+08 | E7: =SUM(E8,E10) -> 2.3967435e+08 | F7: =SUM(F8,F10) -> 3.0542055e+08 | G7: =SUM(G8,G10) -> 3.52725e+08 | H7: =SUM(H8,H10) -> 3.8098314e+08 | I7: =SUM(I8,I10) -> 5.2254876e+08 | J7: =SUM(J8,J10) -> 5.2521408e+08 | ... Z7: =SUM(Z8,Z10) -> 0 | AA7: =C7+E7+G7+I7+K7+M7+O7+Q7+S7+U7+W7+Y7 -> 5.2187376e+09 | AB7: =D7+F7+H7+J7+L7+N7+P7+R7+T7+V7+X7+Z7 -> 2.8635376e+09 | AC7: =IFERROR(AB7/AA7,0) -> 0.54870312
B8: Доход от основной деятельности | C8: =SUM(C9) -> 2.237922e+08 | D8: =SUM(D9) -> 2.8664104e+08 | E8: =SUM(E9) -> 2.3967435e+08 | F8: =SUM(F9) -> 3.0539731e+08 | G8: =SUM(G9) -> 3.52725e+08 | H8: =SUM(H9) -> 3.8095762e+08 | I8: =SUM(I9) -> 5.2254876e+08 | J8: =SUM(J9) -> 5.2520057e+08 | ... Z8: =SUM(Z9) -> 0 | AA8: =SUM(C8,E8,G8,I8,K8,M8,O68,O8,Q8,S8,Y8,W8,U8) -> 5.2187366e+09 | AB8: =D8+F8+H8+J8+L8+N8+P8+R8+T8+V8+X8+Z8 -> 2.8634187e+09 | AC8: =IFERROR(AB8/AA8,0) -> 0.54868045
B9: Доход от основной деятельности | C9: =SUMIFS(data!$G:$G,data!$A:$A,$B$6,data!$B:$B,$B$7,data!$C:$C,$B$8,data!$F:$F,C$4,data!$E:$E,$B9,data!$H:$H,ПФ2026!C$5) -> 2.237922e+08 | D9: =SUMIFS(data!$G:$G,data!$A:$A,$B$6,data!$B:$B,$B$7,data!$C:$C,$B$8,data!$F:$F,C$4,data!$E:$E,$B9,data!$H:$H,ПФ2026!D$5) -> 2.8664104e+08 | E9: =SUMIFS(data!$G:$G,data!$A:$A,$B$6,data!$B:$B,$B$7,data!$C:$C,$B$8,data!$F:$F,E$4,data!$E:$E,$B9,data!$H:$H,ПФ2026!E$5) -> 2.3967435e+08 | F9: =SUMIFS(data!$G:$G,data!$A:$A,$B$6,data!$B:$B,$B$7,data!$C:$C,$B$8,data!$F:$F,E$4,data!$E:$E,$B9,data!$H:$H,ПФ2026!F$5) -> 3.0539731e+08 | G9: =SUMIFS(data!$G:$G,data!$A:$A,$B$6,data!$B:$B,$B$7,data!$C:$C,$B$8,data!$F:$F,G$4,data!$E:$E,$B9,data!$H:$H,ПФ2026!G$5) -> 3.52725e+08 | H9: =SUMIFS(data!$G:$G,data!$A:$A,$B$6,data!$B:$B,$B$7,data!$C:$C,$B$8,data!$F:$F,G$4,data!$E:$E,$B9,data!$H:$H,ПФ2026!H$5) -> 3.8095762e+08 | I9: =SUMIFS(data!$G:$G,data!$A:$A,$B$6,data!$B:$B,$B$7,data!$C:$C,$B$8,data!$F:$F,I$4,data!$E:$E,$B9,data!$H:$H,ПФ2026!I$5) -> 5.2254876e+08 | J9: =SUMIFS(data!$G:$G,data!$A:$A,$B$6,data!$B:$B,$B$7,data!$C:$C,$B$8,data!$F:$F,I$4,data!$E:$E,$B9,data!$H:$H,ПФ2026!J$5) -> 5.2520057e+08 | K9: =SUMIFS(data!$G:$G,data!$A:$A,$B$6,data!$B:$B,$B$7,data!$C:$C,$B$8,data!$F:$F,K$4,data!$E:$E,$B9,data!$H:$H,ПФ2026!K$5) -> 6.219339e+08 | L9: =SUMIFS(data!$G:$G,data!$A:$A,$B$6,data!$B:$B,$B$7,data!$C:$C,$B$8,data!$F:$F,K$4,data!$E:$E,$B9,data!$H:$H,ПФ2026!L$5) -> 5.8823019e+08 | M9: =SUMIFS(data!$G:$G,data!$A:$A,$B$6,data!$B:$B,$B$7,data!$C:$C,$B$8,data!$F:$F,M$4,data!$E:$E,$B9,data!$H:$H,ПФ2026!M$5) -> 6.4493543e+08 | N9: =SUMIFS(data!$G:$G,data!$A:$A,$B$6,data!$B:$B,$B$7,data!$C:$C,$B$8,data!$F:$F,M$4,data!$E:$E,$B9,data!$H:$H,ПФ2026!N$5) -> 7.76992e+08 | O9: =SUMIFS(data!$G:$G,data!$A:$A,$B$6,data!$B:$B,$B$7,data!$C:$C,$B$8,data!$F:$F,O$4,data!$E:$E,$B9,data!$H:$H,ПФ2026!O$5) -> 7.6191424e+08 | P9: =SUMIFS(data!$G:$G,data!$A:$A,$B$6,data!$B:$B,$B$7,data!$C:$C,$B$8,data!$F:$F,O$4,data!$E:$E,$B9,data!$H:$H,ПФ2026!P$5) -> 0 | Q9: =SUMIFS(data!$G:$G,data!$A:$A,$B$6,data!$B:$B,$B$7,data!$C:$C,$B$8,data!$F:$F,Q$4,data!$E:$E,$B9,data!$H:$H,ПФ2026!Q$5) -> 6.6416884e+08 | R9: =SUMIFS(data!$G:$G,data!$A:$A,$B$6,data!$B:$B,$B$7,data!$C:$C,$B$8,data!$F:$F,Q$4,data!$E:$E,$B9,data!$H:$H,ПФ2026!R$5) -> 0 | S9: =SUMIFS(data!$G:$G,data!$A:$A,$B$6,data!$B:$B,$B$7,data!$C:$C,$B$8,data!$F:$F,S$4,data!$E:$E,$B9,data!$H:$H,ПФ2026!S$5) -> 4.4556039e+08 | T9: =SUMIFS(data!$G:$G,data!$A:$A,$B$6,data!$B:$B,$B$7,data!$C:$C,$B$8,data!$F:$F,S$4,data!$E:$E,$B9,data!$H:$H,ПФ2026!T$5) -> 0 | U9: =SUMIFS(data!$G:$G,data!$A:$A,$B$6,data!$B:$B,$B$7,data!$C:$C,$B$8,data!$F:$F,U$4,data!$E:$E,$B9,data!$H:$H,ПФ2026!U$5) -> 2.7591841e+08 | V9: =SUMIFS(data!$G:$G,data!$A:$A,$B$6,data!$B:$B,$B$7,data!$C:$C,$B$8,data!$F:$F,U$4,data!$E:$E,$B9,data!$H:$H,ПФ2026!V$5) -> 0 | W9: =SUMIFS(data!$G:$G,data!$A:$A,$B$6,data!$B:$B,$B$7,data!$C:$C,$B$8,data!$F:$F,W$4,data!$E:$E,$B9,data!$H:$H,ПФ2026!W$5) -> 2.4099837e+08 | X9: =SUMIFS(data!$G:$G,data!$A:$A,$B$6,data!$B:$B,$B$7,data!$C:$C,$B$8,data!$F:$F,W$4,data!$E:$E,$B9,data!$H:$H,ПФ2026!X$5) -> 0 | Y9: =SUMIFS(data!$G:$G,data!$A:$A,$B$6,data!$B:$B,$B$7,data!$C:$C,$B$8,data!$F:$F,Y$4,data!$E:$E,$B9,data!$H:$H,ПФ2026!Y$5) -> 2.2456769e+08 | Z9: =SUMIFS(data!$G:$G,data!$A:$A,$B$6,data!$B:$B,$B$7,data!$C:$C,$B$8,data!$F:$F,Y$4,data!$E:$E,$B9,data!$H:$H,ПФ2026!Z$5) -> 0 | AA9: =SUM(C9,E9,G9,I9,K9,M9,O69,O9,Q9,S9,Y9,W9,U9) -> 5.2187176e+09 | AB9: =D9+F9+H9+J9+L9+N9+P9+R9+T9+V9+X9+Z9 -> 2.8634187e+09 | AC9: =IFERROR(AB9/AA9,0) -> 0.54868245
B10: Доход от неосновной деятельности | C10: =SUM(C11:C12) -> 0 | D10: =SUM(D11:D12) -> 26705 | E10: =SUM(E11:E12) -> 0 | F10: =SUM(F11:F12) -> 23239 | G10: =SUM(G11:G12) -> 0 | H10: =SUM(H11:H12) -> 25523 | I10: =SUM(I11:I12) -> 0 | J10: =SUM(J11:J12) -> 13507.3 | ... Z10: =SUM(Z11:Z12) -> 0 | AA10: =SUM(C10,E10,G10,I10,K10,M10,O70,O10,Q10,S10,Y10,W10,U10) -> -3444440 | AB10: =D10+F10+H10+J10+L10+N10+P10+R10+T10+V10+X10+Z10 -> 118831.6 | AC10: =IFERROR(AB10/AA10,0) -> -0.034499541
B11: Доход от аренды помещений | C11: =SUMIFS(data!$G:$G,data!$A:$A,$B$6,data!$B:$B,$B$7,data!$C:$C,$B$10,data!$F:$F,C$4,data!$E:$E,$B11,data!$H:$H,ПФ2026!C$5) -> 0 | D11: =SUMIFS(data!$G:$G,data!$A:$A,$B$6,data!$B:$B,$B$7,data!$C:$C,$B$10,data!$F:$F,C$4,data!$E:$E,$B11,data!$H:$H,ПФ2026!D$5) -> 1350 | E11: =SUMIFS(data!$G:$G,data!$A:$A,$B$6,data!$B:$B,$B$7,data!$C:$C,$B$10,data!$F:$F,E$4,data!$E:$E,$B11,data!$H:$H,ПФ2026!E$5) -> 0 | F11: =SUMIFS(data!$G:$G,data!$A:$A,$B$6,data!$B:$B,$B$7,data!$C:$C,$B$10,data!$F:$F,E$4,data!$E:$E,$B11,data!$H:$H,ПФ2026!F$5) -> 0 | G11: =SUMIFS(data!$G:$G,data!$A:$A,$B$6,data!$B:$B,$B$7,data!$C:$C,$B$10,data!$F:$F,G$4,data!$E:$E,$B11,data!$H:$H,ПФ2026!G$5) -> 0 | H11: =SUMIFS(data!$G:$G,data!$A:$A,$B$6,data!$B:$B,$B$7,data!$C:$C,$B$10,data!$F:$F,G$4,data!$E:$E,$B11,data!$H:$H,ПФ2026!H$5) -> 3873 | I11: =SUMIFS(data!$G:$G,data!$A:$A,$B$6,data!$B:$B,$B$7,data!$C:$C,$B$10,data!$F:$F,I$4,data!$E:$E,$B11,data!$H:$H,ПФ2026!I$5) -> 0 | J11: =SUMIFS(data!$G:$G,data!$A:$A,$B$6,data!$B:$B,$B$7,data!$C:$C,$B$10,data!$F:$F,I$4,data!$E:$E,$B11,data!$H:$H,ПФ2026!J$5) -> 507.3 | K11: =SUMIFS(data!$G:$G,data!$A:$A,$B$6,data!$B:$B,$B$7,data!$C:$C,$B$10,data!$F:$F,K$4,data!$E:$E,$B11,data!$H:$H,ПФ2026!K$5) -> 0 | L11: =SUMIFS(data!$G:$G,data!$A:$A,$B$6,data!$B:$B,$B$7,data!$C:$C,$B$10,data!$F:$F,K$4,data!$E:$E,$B11,data!$H:$H,ПФ2026!L$5) -> 507.3 | M11: =SUMIFS(data!$G:$G,data!$A:$A,$B$6,data!$B:$B,$B$7,data!$C:$C,$B$10,data!$F:$F,M$4,data!$E:$E,$B11,data!$H:$H,ПФ2026!M$5) -> 0 | N11: =SUMIFS(data!$G:$G,data!$A:$A,$B$6,data!$B:$B,$B$7,data!$C:$C,$B$10,data!$F:$F,M$4,data!$E:$E,$B11,data!$H:$H,ПФ2026!N$5) -> 0 | O11: =SUMIFS(data!$G:$G,data!$A:$A,$B$6,data!$B:$B,$B$7,data!$C:$C,$B$10,data!$F:$F,O$4,data!$E:$E,$B11,data!$H:$H,ПФ2026!O$5) -> 0 | P11: =SUMIFS(data!$G:$G,data!$A:$A,$B$6,data!$B:$B,$B$7,data!$C:$C,$B$10,data!$F:$F,O$4,data!$E:$E,$B11,data!$H:$H,ПФ2026!P$5) -> 0 | Q11: =SUMIFS(data!$G:$G,data!$A:$A,$B$6,data!$B:$B,$B$7,data!$C:$C,$B$10,data!$F:$F,Q$4,data!$E:$E,$B11,data!$H:$H,ПФ2026!Q$5) -> 0 | R11: =SUMIFS(data!$G:$G,data!$A:$A,$B$6,data!$B:$B,$B$7,data!$C:$C,$B$10,data!$F:$F,Q$4,data!$E:$E,$B11,data!$H:$H,ПФ2026!R$5) -> 0 | S11: =SUMIFS(data!$G:$G,data!$A:$A,$B$6,data!$B:$B,$B$7,data!$C:$C,$B$10,data!$F:$F,S$4,data!$E:$E,$B11,data!$H:$H,ПФ2026!S$5) -> 0 | T11: =SUMIFS(data!$G:$G,data!$A:$A,$B$6,data!$B:$B,$B$7,data!$C:$C,$B$10,data!$F:$F,S$4,data!$E:$E,$B11,data!$H:$H,ПФ2026!T$5) -> 0 | U11: =SUMIFS(data!$G:$G,data!$A:$A,$B$6,data!$B:$B,$B$7,data!$C:$C,$B$10,data!$F:$F,U$4,data!$E:$E,$B11,data!$H:$H,ПФ2026!U$5) -> 0 | V11: =SUMIFS(data!$G:$G,data!$A:$A,$B$6,data!$B:$B,$B$7,data!$C:$C,$B$10,data!$F:$F,U$4,data!$E:$E,$B11,data!$H:$H,ПФ2026!V$5) -> 0 | W11: =SUMIFS(data!$G:$G,data!$A:$A,$B$6,data!$B:$B,$B$7,data!$C:$C,$B$10,data!$F:$F,W$4,data!$E:$E,$B11,data!$H:$H,ПФ2026!W$5) -> 0 | X11: =SUMIFS(data!$G:$G,data!$A:$A,$B$6,data!$B:$B,$B$7,data!$C:$C,$B$10,data!$F:$F,W$4,data!$E:$E,$B11,data!$H:$H,ПФ2026!X$5) -> 0 | Y11: =SUMIFS(data!$G:$G,data!$A:$A,$B$6,data!$B:$B,$B$7,data!$C:$C,$B$10,data!$F:$F,Y$4,data!$E:$E,$B11,data!$H:$H,ПФ2026!Y$5) -> 0 | Z11: =SUMIFS(data!$G:$G,data!$A:$A,$B$6,data!$B:$B,$B$7,data!$C:$C,$B$10,data!$F:$F,Y$4,data!$E:$E,$B11,data!$H:$H,ПФ2026!Z$5) -> 0 | AA11: =SUM(C11,E11,G11,I11,K11,M11,O71,O11,Q11,S11) -> -3000000 | AB11: =SUM(D11,F11,H11,J11,L11,N11,P71,P11,R11,T11) -> 6237.6 | AC11: =IFERROR(AB11/AA11,0) -> -0.0020792
B12: Доход от услуг | C12: =SUMIFS(data!$G:$G,data!$A:$A,$B$6,data!$B:$B,$B$7,data!$C:$C,$B$10,data!$F:$F,C$4,data!$E:$E,$B12,data!$H:$H,ПФ2026!C$5) -> 0 | D12: =SUMIFS(data!$G:$G,data!$A:$A,$B$6,data!$B:$B,$B$7,data!$C:$C,$B$10,data!$F:$F,C$4,data!$E:$E,$B12,data!$H:$H,ПФ2026!D$5) -> 25355 | E12: =SUMIFS(data!$G:$G,data!$A:$A,$B$6,data!$B:$B,$B$7,data!$C:$C,$B$10,data!$F:$F,E$4,data!$E:$E,$B12,data!$H:$H,ПФ2026!E$5) -> 0 | F12: =SUMIFS(data!$G:$G,data!$A:$A,$B$6,data!$B:$B,$B$7,data!$C:$C,$B$10,data!$F:$F,E$4,data!$E:$E,$B12,data!$H:$H,ПФ2026!F$5) -> 23239 | G12: =SUMIFS(data!$G:$G,data!$A:$A,$B$6,data!$B:$B,$B$7,data!$C:$C,$B$10,data!$F:$F,G$4,data!$E:$E,$B12,data!$H:$H,ПФ2026!G$5) -> 0 | H12: =SUMIFS(data!$G:$G,data!$A:$A,$B$6,data!$B:$B,$B$7,data!$C:$C,$B$10,data!$F:$F,G$4,data!$E:$E,$B12,data!$H:$H,ПФ2026!H$5) -> 21650 | I12: =SUMIFS(data!$G:$G,data!$A:$A,$B$6,data!$B:$B,$B$7,data!$C:$C,$B$10,data!$F:$F,I$4,data!$E:$E,$B12,data!$H:$H,ПФ2026!I$5) -> 0 | J12: =SUMIFS(data!$G:$G,data!$A:$A,$B$6,data!$B:$B,$B$7,data!$C:$C,$B$10,data!$F:$F,I$4,data!$E:$E,$B12,data!$H:$H,ПФ2026!J$5) -> 13000 | K12: =SUMIFS(data!$G:$G,data!$A:$A,$B$6,data!$B:$B,$B$7,data!$C:$C,$B$10,data!$F:$F,K$4,data!$E:$E,$B12,data!$H:$H,ПФ2026!K$5) -> 0 | L12: =SUMIFS(data!$G:$G,data!$A:$A,$B$6,data!$B:$B,$B$7,data!$C:$C,$B$10,data!$F:$F,K$4,data!$E:$E,$B12,data!$H:$H,ПФ2026!L$5) -> 9850 | M12: =SUMIFS(data!$G:$G,data!$A:$A,$B$6,data!$B:$B,$B$7,data!$C:$C,$B$10,data!$F:$F,M$4,data!$E:$E,$B12,data!$H:$H,ПФ2026!M$5) -> 0 | N12: =SUMIFS(data!$G:$G,data!$A:$A,$B$6,data!$B:$B,$B$7,data!$C:$C,$B$10,data!$F:$F,M$4,data!$E:$E,$B12,data!$H:$H,ПФ2026!N$5) -> 19500 | O12: =SUMIFS(data!$G:$G,data!$A:$A,$B$6,data!$B:$B,$B$7,data!$C:$C,$B$10,data!$F:$F,O$4,data!$E:$E,$B12,data!$H:$H,ПФ2026!O$5) -> 0 | P12: =SUMIFS(data!$G:$G,data!$A:$A,$B$6,data!$B:$B,$B$7,data!$C:$C,$B$10,data!$F:$F,O$4,data!$E:$E,$B12,data!$H:$H,ПФ2026!P$5) -> 0 | Q12: =SUMIFS(data!$G:$G,data!$A:$A,$B$6,data!$B:$B,$B$7,data!$C:$C,$B$10,data!$F:$F,Q$4,data!$E:$E,$B12,data!$H:$H,ПФ2026!Q$5) -> 0 | R12: =SUMIFS(data!$G:$G,data!$A:$A,$B$6,data!$B:$B,$B$7,data!$C:$C,$B$10,data!$F:$F,Q$4,data!$E:$E,$B12,data!$H:$H,ПФ2026!R$5) -> 0 | S12: =SUMIFS(data!$G:$G,data!$A:$A,$B$6,data!$B:$B,$B$7,data!$C:$C,$B$10,data!$F:$F,S$4,data!$E:$E,$B12,data!$H:$H,ПФ2026!S$5) -> 0 | T12: =SUMIFS(data!$G:$G,data!$A:$A,$B$6,data!$B:$B,$B$7,data!$C:$C,$B$10,data!$F:$F,S$4,data!$E:$E,$B12,data!$H:$H,ПФ2026!T$5) -> 0 | U12: =SUMIFS(data!$G:$G,data!$A:$A,$B$6,data!$B:$B,$B$7,data!$C:$C,$B$10,data!$F:$F,U$4,data!$E:$E,$B12,data!$H:$H,ПФ2026!U$5) -> 0 | V12: =SUMIFS(data!$G:$G,data!$A:$A,$B$6,data!$B:$B,$B$7,data!$C:$C,$B$10,data!$F:$F,U$4,data!$E:$E,$B12,data!$H:$H,ПФ2026!V$5) -> 0 | W12: =SUMIFS(data!$G:$G,data!$A:$A,$B$6,data!$B:$B,$B$7,data!$C:$C,$B$10,data!$F:$F,W$4,data!$E:$E,$B12,data!$H:$H,ПФ2026!W$5) -> 0 | X12: =SUMIFS(data!$G:$G,data!$A:$A,$B$6,data!$B:$B,$B$7,data!$C:$C,$B$10,data!$F:$F,W$4,data!$E:$E,$B12,data!$H:$H,ПФ2026!X$5) -> 0 | Y12: =SUMIFS(data!$G:$G,data!$A:$A,$B$6,data!$B:$B,$B$7,data!$C:$C,$B$10,data!$F:$F,Y$4,data!$E:$E,$B12,data!$H:$H,ПФ2026!Y$5) -> 0 | Z12: =SUMIFS(data!$G:$G,data!$A:$A,$B$6,data!$B:$B,$B$7,data!$C:$C,$B$10,data!$F:$F,Y$4,data!$E:$E,$B12,data!$H:$H,ПФ2026!Z$5) -> 0 | AA12: =SUM(C12,E12,G12,I12,K12,M12,O72,O12,Q12,S12) -> -7392 | AB12: =SUM(D12,F12,H12,J12,L12,N12,P72,P12,R12,T12) -> 112594 | AC12: =IFERROR(AB12/AA12,0) -> -15.231872
B13: Расходы по себестоимости | C13: =SUM(C28,C18,C24,C14,C16) -> -90651724 | D13: =SUM(D28,D18,D24,D14,D16) -> -1.2367951e+08 | E13: =SUM(E28,E18,E24,E14,E16) -> -95028669 | F13: =SUM(F28,F18,F24,F14,F16) -> -1.3032997e+08 | G13: =SUM(G28,G18,G24,G14,G16) -> -1.2675685e+08 | H13: =SUM(H28,H18,H24,H14,H16) -> -1.4390889e+08 | I13: =SUM(I28,I18,I24,I14,I16) -> -1.7005785e+08 | J13: =SUM(J28,J18,J24,J14,J16) -> -1.7408157e+08 | ... Z13: =SUM(Z28,Z18,Z24,Z14,Z16) -> 0 | AA13: =C13+E13+G13+I13+K13+M13+O13+Q13+S13+U13+W13+Y13 -> -1.795177e+09 | AB13: =D13+F13+H13+J13+L13+N13+P13+R13+T13+V13+X13+Z13 -> -9.9371601e+08 | AC13: =IFERROR(AB13/AA13,0) -> 0.55354765
B14: Расходы по себестоимости сырья | C14: =SUM(C15) -> -67359643 | D14: =SUM(D15) -> -33676713 | E14: =SUM(E15) -> -70752129 | F14: =SUM(F15) -> -37079022 | G14: =SUM(G15) -> -1.0007111e+08 | H14: =SUM(H15) -> -26397344 | I14: =SUM(I15) -> -1.3897355e+08 | J14: =SUM(J15) -> -1.3601143e+08 | ... Z14: =SUM(Z15) -> 0 | AA14: =SUM(C14,E14,G14,I14,K14,M14,O74,O14,Q14,S14,Y14,W14,U14) -> -1.4102048e+09 | AB14: =D14+F14+H14+J14+L14+N14+P14+R14+T14+V14+X14+Z14 -> -5.023857e+08 | AC14: =IFERROR(AB14/AA14,0) -> 0.35625016
B15: Расходы по себестоимости сырья | C15: =SUMIFS(data!$G:$G,data!$C:$C,$B$13,data!$D:$D,$B$14,data!$F:$F,C$4,data!$E:$E,$B15,data!$H:$H,ПФ2026!C$5) -> -67359643 | D15: =Лист4!C$10 -> -33676713 | E15: =SUMIFS(data!$G:$G,data!$C:$C,$B$13,data!$D:$D,$B$14,data!$F:$F,E$4,data!$E:$E,$B15,data!$H:$H,ПФ2026!E$5) -> -70752129 | F15: =Лист4!D$10 -> -37079022 | G15: =SUMIFS(data!$G:$G,data!$C:$C,$B$13,data!$D:$D,$B$14,data!$F:$F,G$4,data!$E:$E,$B15,data!$H:$H,ПФ2026!G$5) -> -1.0007111e+08 | H15: =Лист4!E$10 -> -26397344 | I15: =SUMIFS(data!$G:$G,data!$C:$C,$B$13,data!$D:$D,$B$14,data!$F:$F,I$4,data!$E:$E,$B15,data!$H:$H,ПФ2026!I$5) -> -1.3897355e+08 | J15: =Лист4!F$10 -> -1.3601143e+08 | K15: =SUMIFS(data!$G:$G,data!$C:$C,$B$13,data!$D:$D,$B$14,data!$F:$F,K$4,data!$E:$E,$B15,data!$H:$H,ПФ2026!K$5) -> -1.5903949e+08 | L15: =Лист4!G$10 -> -82862751 | M15: =SUMIFS(data!$G:$G,data!$C:$C,$B$13,data!$D:$D,$B$14,data!$F:$F,M$4,data!$E:$E,$B15,data!$H:$H,ПФ2026!M$5) -> -1.6343569e+08 | N15: =Лист4!H$10 -> -1.8635845e+08 | O15: =SUMIFS(data!$G:$G,data!$C:$C,$B$13,data!$D:$D,$B$14,data!$F:$F,O$4,data!$E:$E,$B15,data!$H:$H,ПФ2026!O$5) -> -1.9813763e+08 | P15: =Лист4!I10 -> 0 | Q15: =SUMIFS(data!$G:$G,data!$C:$C,$B$13,data!$D:$D,$B$14,data!$F:$F,Q$4,data!$E:$E,$B15,data!$H:$H,ПФ2026!Q$5) -> -1.7099779e+08 | R15: =Лист4!J$10 -> 0 | S15: =SUMIFS(data!$G:$G,data!$C:$C,$B$13,data!$D:$D,$B$14,data!$F:$F,S$4,data!$E:$E,$B15,data!$H:$H,ПФ2026!S$5) -> -1.204398e+08 | T15: =Лист4!K$10 -> 0 | U15: =SUMIFS(data!$G:$G,data!$C:$C,$B$13,data!$D:$D,$B$14,data!$F:$F,U$4,data!$E:$E,$B15,data!$H:$H,ПФ2026!U$5) -> -81391996 | V15: =Лист4!L$10 -> 0 | W15: =SUMIFS(data!$G:$G,data!$C:$C,$B$13,data!$D:$D,$B$14,data!$F:$F,W$4,data!$E:$E,$B15,data!$H:$H,ПФ2026!W$5) -> -71544691 | X15: =Лист4!M10 -> 0 | Y15: =SUMIFS(data!$G:$G,data!$C:$C,$B$13,data!$D:$D,$B$14,data!$F:$F,Y$4,data!$E:$E,$B15,data!$H:$H,ПФ2026!Y$5) -> -68061325 | Z15: =Лист4!N$10 -> 0 | AA15: =SUM(C15,E15,G15,I15,K15,M15,O75,O15,Q15,S15,Y15,W15,U15) -> -1.4102478e+09 | AB15: =D15+F15+H15+J15+L15+N15+P15+R15+T15+V15+X15+Z15 -> -5.023857e+08 | AC15: =IFERROR(AB15/AA15,0) -> 0.35623931
B16: Расходы по себестоимости ФЗП | C16: =SUM(C17) -> -8435387.7 | D16: =SUM(D17) -> -72257022 | E16: =SUM(E17) -> -8863141.7 | F16: =SUM(F17) -> -75683712 | G16: =SUM(G17) -> -11643726 | H16: =SUM(H17) -> -99102968 | I16: =SUM(I17) -> -15237070 | J16: =SUM(J17) -> -19217075 | ... Z16: =SUM(Z17) -> 0 | AA16: =SUM(C16,E16,G16,I16,K16,M16,O76,O16,Q16,S16,Y16,W16,U16) -> -1.5795897e+08 | AB16: =D16+F16+H16+J16+L16+N16+P16+R16+T16+V16+X16+Z16 -> -3.7850048e+08 | AC16: =IFERROR(AB16/AA16,0) -> 2.3961949
B17: Расходы по себестоимости ФЗП | C17: =SUMIFS(data!$G:$G,data!$C:$C,$B$13,data!$D:$D,$B$16,data!$F:$F,C$4,data!$E:$E,$B17,data!$H:$H,ПФ2026!C$5) -> -8435387.7 | D17: =Лист4!$C$6*ПФ2026!$C$1 -> -72257022 | E17: =SUMIFS(data!$G:$G,data!$C:$C,$B$13,data!$D:$D,$B$16,data!$F:$F,E$4,data!$E:$E,$B17,data!$H:$H,ПФ2026!E$5) -> -8863141.7 | F17: =Лист4!$D$6*ПФ2026!$C$1 -> -75683712 | G17: =SUMIFS(data!$G:$G,data!$C:$C,$B$13,data!$D:$D,$B$16,data!$F:$F,G$4,data!$E:$E,$B17,data!$H:$H,ПФ2026!G$5) -> -11643726 | H17: =Лист4!$E$6*ПФ2026!$C$1 -> -99102968 | I17: =SUMIFS(data!$G:$G,data!$C:$C,$B$13,data!$D:$D,$B$16,data!$F:$F,I$4,data!$E:$E,$B17,data!$H:$H,ПФ2026!I$5) -> -15237070 | J17: =Лист4!$F$6*ПФ2026!$C$1 -> -19217075 | K17: =SUMIFS(data!$G:$G,data!$C:$C,$B$13,data!$D:$D,$B$16,data!$F:$F,K$4,data!$E:$E,$B17,data!$H:$H,ПФ2026!K$5) -> -17101214 | L17: =Лист4!$G$6*ПФ2026!$C$1 -> -87639122 | M17: =SUMIFS(data!$G:$G,data!$C:$C,$B$13,data!$D:$D,$B$16,data!$F:$F,M$4,data!$E:$E,$B17,data!$H:$H,ПФ2026!M$5) -> -17299414 | N17: =Лист4!$H$6*ПФ2026!$C$1 -> -24600578 | O17: =SUMIFS(data!$G:$G,data!$C:$C,$B$13,data!$D:$D,$B$16,data!$F:$F,O$4,data!$E:$E,$B17,data!$H:$H,ПФ2026!O$5) -> -19625381 | P17: =Лист4!I6*ПФ2026!C1 -> 0 | Q17: =SUMIFS(data!$G:$G,data!$C:$C,$B$13,data!$D:$D,$B$16,data!$F:$F,Q$4,data!$E:$E,$B17,data!$H:$H,ПФ2026!Q$5) -> -17512321 | R17: =Лист4!J6*ПФ2026!C1 -> 0 | S17: =SUMIFS(data!$G:$G,data!$C:$C,$B$13,data!$D:$D,$B$16,data!$F:$F,S$4,data!$E:$E,$B17,data!$H:$H,ПФ2026!S$5) -> -13455184 | T17: =Лист4!K6*ПФ2026!C1 -> 0 | U17: =SUMIFS(data!$G:$G,data!$C:$C,$B$13,data!$D:$D,$B$16,data!$F:$F,U$4,data!$E:$E,$B17,data!$H:$H,ПФ2026!U$5) -> -10852136 | V17: =Лист4!L6*ПФ2026!C1 -> 0 | W17: =SUMIFS(data!$G:$G,data!$C:$C,$B$13,data!$D:$D,$B$16,data!$F:$F,W$4,data!$E:$E,$B17,data!$H:$H,ПФ2026!W$5) -> -9084947.6 | X17: =Лист4!M6*ПФ2026!$C$1 -> 0 | Y17: =SUMIFS(data!$G:$G,data!$C:$C,$B$13,data!$D:$D,$B$16,data!$F:$F,Y$4,data!$E:$E,$B17,data!$H:$H,ПФ2026!Y$5) -> -8849046.9 | Z17: =Лист4!N6*ПФ2026!$C$1 -> 0 | AA17: =SUM(C17,E17,G17,I17,K17,M17,O77,O17,Q17,S17,Y17,W17,U17) -> -1.5795897e+08 | AB17: =D17+F17+H17+J17+L17+N17+P17+R17+T17+V17+X17+Z17 -> -3.7850048e+08 | AC17: =IFERROR(AB17/AA17,0) -> 2.3961949
B18: Расходы по амортизации | C18: =SUM(C19:C23) -> -12461257 | D18: =SUM(D19:D23) -> -15012436 | E18: =SUM(E19:E23) -> -12378828 | F18: =SUM(F19:F23) -> -14735429 | G18: =SUM(G19:G23) -> -12651670 | H18: =SUM(H19:H23) -> -14783266 | I18: =SUM(I19:I23) -> -12566183 | J18: =SUM(J19:J23) -> -14812631 | ... Z18: =SUM(Z19:Z23) -> 0 | AA18: =SUM(C18,E18,G18,I18,K18,M18,O78,O18,Q18,S18,Y18,W18,U18) -> -1.8242903e+08 | AB18: =D18+F18+H18+J18+L18+N18+P18+R18+T18+V18+X18+Z18 -> -88001062 | AC18: =IFERROR(AB18/AA18,0) -> 0.48238518
B19: 2130/Амортизация - здания | C19: =SUMIFS(data!$G:$G,data!$C:$C,$B$13,data!$D:$D,$B$18,data!$F:$F,C$4,data!$E:$E,$B19,data!$H:$H,ПФ2026!C$5) -> -208621.29 | D19: =SUMIFS(data!$G:$G,data!$C:$C,$B$13,data!$D:$D,$B$18,data!$F:$F,C$4,data!$E:$E,$B19,data!$H:$H,ПФ2026!D$5) -> -705549.66 | E19: =SUMIFS(data!$G:$G,data!$C:$C,$B$13,data!$D:$D,$B$18,data!$F:$F,E$4,data!$E:$E,$B19,data!$H:$H,ПФ2026!E$5) -> -208621.29 | F19: =SUMIFS(data!$G:$G,data!$C:$C,$B$13,data!$D:$D,$B$18,data!$F:$F,E$4,data!$E:$E,$B19,data!$H:$H,ПФ2026!F$5) -> -705549.66 | G19: =SUMIFS(data!$G:$G,data!$C:$C,$B$13,data!$D:$D,$B$18,data!$F:$F,G$4,data!$E:$E,$B19,data!$H:$H,ПФ2026!G$5) -> -209785.24 | H19: =SUMIFS(data!$G:$G,data!$C:$C,$B$13,data!$D:$D,$B$18,data!$F:$F,G$4,data!$E:$E,$B19,data!$H:$H,ПФ2026!H$5) -> -729713.45 | I19: =SUMIFS(data!$G:$G,data!$C:$C,$B$13,data!$D:$D,$B$18,data!$F:$F,I$4,data!$E:$E,$B19,data!$H:$H,ПФ2026!I$5) -> -211606.22 | J19: =SUMIFS(data!$G:$G,data!$C:$C,$B$13,data!$D:$D,$B$18,data!$F:$F,I$4,data!$E:$E,$B19,data!$H:$H,ПФ2026!J$5) -> -738480.85 | K19: =SUMIFS(data!$G:$G,data!$C:$C,$B$13,data!$D:$D,$B$18,data!$F:$F,K$4,data!$E:$E,$B19,data!$H:$H,ПФ2026!K$5) -> -214246.72 | L19: =SUMIFS(data!$G:$G,data!$C:$C,$B$13,data!$D:$D,$B$18,data!$F:$F,K$4,data!$E:$E,$B19,data!$H:$H,ПФ2026!L$5) -> -756590.19 | M19: =SUMIFS(data!$G:$G,data!$C:$C,$B$13,data!$D:$D,$B$18,data!$F:$F,M$4,data!$E:$E,$B19,data!$H:$H,ПФ2026!M$5) -> -214246.72 | N19: =SUMIFS(data!$G:$G,data!$C:$C,$B$13,data!$D:$D,$B$18,data!$F:$F,M$4,data!$E:$E,$B19,data!$H:$H,ПФ2026!N$5) -> -753239.62 | O19: =SUMIFS(data!$G:$G,data!$C:$C,$B$13,data!$D:$D,$B$18,data!$F:$F,O$4,data!$E:$E,$B19,data!$H:$H,ПФ2026!O$5) -> -249829.13 | P19: =SUMIFS(data!$G:$G,data!$C:$C,$B$13,data!$D:$D,$B$18,data!$F:$F,O$4,data!$E:$E,$B19,data!$H:$H,ПФ2026!P$5) -> 0 | Q19: =SUMIFS(data!$G:$G,data!$C:$C,$B$13,data!$D:$D,$B$18,data!$F:$F,Q$4,data!$E:$E,$B19,data!$H:$H,ПФ2026!Q$5) -> -257035.1 | R19: =SUMIFS(data!$G:$G,data!$C:$C,$B$13,data!$D:$D,$B$18,data!$F:$F,Q$4,data!$E:$E,$B19,data!$H:$H,ПФ2026!R$5) -> 0 | S19: =SUMIFS(data!$G:$G,data!$C:$C,$B$13,data!$D:$D,$B$18,data!$F:$F,S$4,data!$E:$E,$B19,data!$H:$H,ПФ2026!S$5) -> -503329.73 | T19: =SUMIFS(data!$G:$G,data!$C:$C,$B$13,data!$D:$D,$B$18,data!$F:$F,S$4,data!$E:$E,$B19,data!$H:$H,ПФ2026!T$5) -> 0 | U19: =SUMIFS(data!$G:$G,data!$C:$C,$B$13,data!$D:$D,$B$18,data!$F:$F,U$4,data!$E:$E,$B19,data!$H:$H,ПФ2026!U$5) -> -776193.55 | V19: =SUMIFS(data!$G:$G,data!$C:$C,$B$13,data!$D:$D,$B$18,data!$F:$F,U$4,data!$E:$E,$B19,data!$H:$H,ПФ2026!V$5) -> 0 | W19: =SUMIFS(data!$G:$G,data!$C:$C,$B$13,data!$D:$D,$B$18,data!$F:$F,W$4,data!$E:$E,$B19,data!$H:$H,ПФ2026!W$5) -> -730718.12 | X19: =SUMIFS(data!$G:$G,data!$C:$C,$B$13,data!$D:$D,$B$18,data!$F:$F,W$4,data!$E:$E,$B19,data!$H:$H,ПФ2026!X$5) -> 0 | Y19: =SUMIFS(data!$G:$G,data!$C:$C,$B$13,data!$D:$D,$B$18,data!$F:$F,Y$4,data!$E:$E,$B19,data!$H:$H,ПФ2026!Y$5) -> -739809.42 | Z19: =SUMIFS(data!$G:$G,data!$C:$C,$B$13,data!$D:$D,$B$18,data!$F:$F,Y$4,data!$E:$E,$B19,data!$H:$H,ПФ2026!Z$5) -> 0 | AA19: =SUM(C19,E19,G19,I19,K19,M19,O79,O19,Q19,S19,Y19,W19,U19) -> -5304442.5 | AB19: =D19+F19+H19+J19+L19+N19+P19+R19+T19+V19+X19+Z19 -> -4389123.4 | AC19: =IFERROR(AB19/AA19,0) -> 0.82744292
B20: 2140/Амортизация - оборудование | C20: =SUMIFS(data!$G:$G,data!$C:$C,$B$13,data!$D:$D,$B$18,data!$F:$F,C$4,data!$E:$E,$B20,data!$H:$H,ПФ2026!C$5) -> -12193821 | D20: =SUMIFS(data!$G:$G,data!$C:$C,$B$13,data!$D:$D,$B$18,data!$F:$F,C$4,data!$E:$E,$B20,data!$H:$H,ПФ2026!D$5) -> -14306887 | E20: =SUMIFS(data!$G:$G,data!$C:$C,$B$13,data!$D:$D,$B$18,data!$F:$F,E$4,data!$E:$E,$B20,data!$H:$H,ПФ2026!E$5) -> -12108590 | F20: =SUMIFS(data!$G:$G,data!$C:$C,$B$13,data!$D:$D,$B$18,data!$F:$F,E$4,data!$E:$E,$B20,data!$H:$H,ПФ2026!F$5) -> -14029880 | G20: =SUMIFS(data!$G:$G,data!$C:$C,$B$13,data!$D:$D,$B$18,data!$F:$F,G$4,data!$E:$E,$B20,data!$H:$H,ПФ2026!G$5) -> -12373983 | H20: =SUMIFS(data!$G:$G,data!$C:$C,$B$13,data!$D:$D,$B$18,data!$F:$F,G$4,data!$E:$E,$B20,data!$H:$H,ПФ2026!H$5) -> -14053552 | I20: =SUMIFS(data!$G:$G,data!$C:$C,$B$13,data!$D:$D,$B$18,data!$F:$F,I$4,data!$E:$E,$B20,data!$H:$H,ПФ2026!I$5) -> -12285981 | J20: =SUMIFS(data!$G:$G,data!$C:$C,$B$13,data!$D:$D,$B$18,data!$F:$F,I$4,data!$E:$E,$B20,data!$H:$H,ПФ2026!J$5) -> -14074150 | K20: =SUMIFS(data!$G:$G,data!$C:$C,$B$13,data!$D:$D,$B$18,data!$F:$F,K$4,data!$E:$E,$B20,data!$H:$H,ПФ2026!K$5) -> -11662422 | L20: =SUMIFS(data!$G:$G,data!$C:$C,$B$13,data!$D:$D,$B$18,data!$F:$F,K$4,data!$E:$E,$B20,data!$H:$H,ПФ2026!L$5) -> -13817271 | M20: =SUMIFS(data!$G:$G,data!$C:$C,$B$13,data!$D:$D,$B$18,data!$F:$F,M$4,data!$E:$E,$B20,data!$H:$H,ПФ2026!M$5) -> -12001174 | N20: =SUMIFS(data!$G:$G,data!$C:$C,$B$13,data!$D:$D,$B$18,data!$F:$F,M$4,data!$E:$E,$B20,data!$H:$H,ПФ2026!N$5) -> -13330199 | O20: =SUMIFS(data!$G:$G,data!$C:$C,$B$13,data!$D:$D,$B$18,data!$F:$F,O$4,data!$E:$E,$B20,data!$H:$H,ПФ2026!O$5) -> -12131877 | P20: =SUMIFS(data!$G:$G,data!$C:$C,$B$13,data!$D:$D,$B$18,data!$F:$F,O$4,data!$E:$E,$B20,data!$H:$H,ПФ2026!P$5) -> 0 | Q20: =SUMIFS(data!$G:$G,data!$C:$C,$B$13,data!$D:$D,$B$18,data!$F:$F,Q$4,data!$E:$E,$B20,data!$H:$H,ПФ2026!Q$5) -> -12237341 | R20: =SUMIFS(data!$G:$G,data!$C:$C,$B$13,data!$D:$D,$B$18,data!$F:$F,Q$4,data!$E:$E,$B20,data!$H:$H,ПФ2026!R$5) -> 0 | S20: =SUMIFS(data!$G:$G,data!$C:$C,$B$13,data!$D:$D,$B$18,data!$F:$F,S$4,data!$E:$E,$B20,data!$H:$H,ПФ2026!S$5) -> -24102184 | T20: =SUMIFS(data!$G:$G,data!$C:$C,$B$13,data!$D:$D,$B$18,data!$F:$F,S$4,data!$E:$E,$B20,data!$H:$H,ПФ2026!T$5) -> 0 | U20: =SUMIFS(data!$G:$G,data!$C:$C,$B$13,data!$D:$D,$B$18,data!$F:$F,U$4,data!$E:$E,$B20,data!$H:$H,ПФ2026!U$5) -> -18274474 | V20: =SUMIFS(data!$G:$G,data!$C:$C,$B$13,data!$D:$D,$B$18,data!$F:$F,U$4,data!$E:$E,$B20,data!$H:$H,ПФ2026!V$5) -> 0 | W20: =SUMIFS(data!$G:$G,data!$C:$C,$B$13,data!$D:$D,$B$18,data!$F:$F,W$4,data!$E:$E,$B20,data!$H:$H,ПФ2026!W$5) -> -18302843 | X20: =SUMIFS(data!$G:$G,data!$C:$C,$B$13,data!$D:$D,$B$18,data!$F:$F,W$4,data!$E:$E,$B20,data!$H:$H,ПФ2026!X$5) -> 0 | Y20: =SUMIFS(data!$G:$G,data!$C:$C,$B$13,data!$D:$D,$B$18,data!$F:$F,Y$4,data!$E:$E,$B20,data!$H:$H,ПФ2026!Y$5) -> -17553918 | Z20: =SUMIFS(data!$G:$G,data!$C:$C,$B$13,data!$D:$D,$B$18,data!$F:$F,Y$4,data!$E:$E,$B20,data!$H:$H,ПФ2026!Z$5) -> 0 | AA20: =SUM(C20,E20,G20,I20,K20,M20,O80,O20,Q20,S20,Y20,W20,U20) -> -1.7523361e+08 | AB20: =D20+F20+H20+J20+L20+N20+P20+R20+T20+V20+X20+Z20 -> -83611938 | AC20: =IFERROR(AB20/AA20,0) -> 0.47714557
B21: 2150/Амортизация - конторское оборудование | C21: =SUMIFS(data!$G:$G,data!$C:$C,$B$13,data!$D:$D,$B$18,data!$F:$F,C$4,data!$E:$E,$B21,data!$H:$H,ПФ2026!C$5) -> -18713.117 | D21: =SUMIFS(data!$G:$G,data!$C:$C,$B$13,data!$D:$D,$B$18,data!$F:$F,C$4,data!$E:$E,$B21,data!$H:$H,ПФ2026!D$5) -> 0 | E21: =SUMIFS(data!$G:$G,data!$C:$C,$B$13,data!$D:$D,$B$18,data!$F:$F,E$4,data!$E:$E,$B21,data!$H:$H,ПФ2026!E$5) -> -20553.907 | F21: =SUMIFS(data!$G:$G,data!$C:$C,$B$13,data!$D:$D,$B$18,data!$F:$F,E$4,data!$E:$E,$B21,data!$H:$H,ПФ2026!F$5) -> 0 | G21: =SUMIFS(data!$G:$G,data!$C:$C,$B$13,data!$D:$D,$B$18,data!$F:$F,G$4,data!$E:$E,$B21,data!$H:$H,ПФ2026!G$5) -> -23668.073 | H21: =SUMIFS(data!$G:$G,data!$C:$C,$B$13,data!$D:$D,$B$18,data!$F:$F,G$4,data!$E:$E,$B21,data!$H:$H,ПФ2026!H$5) -> 0 | I21: =SUMIFS(data!$G:$G,data!$C:$C,$B$13,data!$D:$D,$B$18,data!$F:$F,I$4,data!$E:$E,$B21,data!$H:$H,ПФ2026!I$5) -> -24362.896 | J21: =SUMIFS(data!$G:$G,data!$C:$C,$B$13,data!$D:$D,$B$18,data!$F:$F,I$4,data!$E:$E,$B21,data!$H:$H,ПФ2026!J$5) -> 0 | K21: =SUMIFS(data!$G:$G,data!$C:$C,$B$13,data!$D:$D,$B$18,data!$F:$F,K$4,data!$E:$E,$B21,data!$H:$H,ПФ2026!K$5) -> -22522.106 | L21: =SUMIFS(data!$G:$G,data!$C:$C,$B$13,data!$D:$D,$B$18,data!$F:$F,K$4,data!$E:$E,$B21,data!$H:$H,ПФ2026!L$5) -> 0 | M21: =SUMIFS(data!$G:$G,data!$C:$C,$B$13,data!$D:$D,$B$18,data!$F:$F,M$4,data!$E:$E,$B21,data!$H:$H,ПФ2026!M$5) -> -24362.896 | N21: =SUMIFS(data!$G:$G,data!$C:$C,$B$13,data!$D:$D,$B$18,data!$F:$F,M$4,data!$E:$E,$B21,data!$H:$H,ПФ2026!N$5) -> 0 | O21: =SUMIFS(data!$G:$G,data!$C:$C,$B$13,data!$D:$D,$B$18,data!$F:$F,O$4,data!$E:$E,$B21,data!$H:$H,ПФ2026!O$5) -> -22771.154 | P21: =SUMIFS(data!$G:$G,data!$C:$C,$B$13,data!$D:$D,$B$18,data!$F:$F,O$4,data!$E:$E,$B21,data!$H:$H,ПФ2026!P$5) -> 0 | Q21: =SUMIFS(data!$G:$G,data!$C:$C,$B$13,data!$D:$D,$B$18,data!$F:$F,Q$4,data!$E:$E,$B21,data!$H:$H,ПФ2026!Q$5) -> -21191.321 | R21: =SUMIFS(data!$G:$G,data!$C:$C,$B$13,data!$D:$D,$B$18,data!$F:$F,Q$4,data!$E:$E,$B21,data!$H:$H,ПФ2026!R$5) -> 0 | S21: =SUMIFS(data!$G:$G,data!$C:$C,$B$13,data!$D:$D,$B$18,data!$F:$F,S$4,data!$E:$E,$B21,data!$H:$H,ПФ2026!S$5) -> -39070.931 | T21: =SUMIFS(data!$G:$G,data!$C:$C,$B$13,data!$D:$D,$B$18,data!$F:$F,S$4,data!$E:$E,$B21,data!$H:$H,ПФ2026!T$5) -> 0 | U21: =SUMIFS(data!$G:$G,data!$C:$C,$B$13,data!$D:$D,$B$18,data!$F:$F,U$4,data!$E:$E,$B21,data!$H:$H,ПФ2026!U$5) -> -20154.678 | V21: =SUMIFS(data!$G:$G,data!$C:$C,$B$13,data!$D:$D,$B$18,data!$F:$F,U$4,data!$E:$E,$B21,data!$H:$H,ПФ2026!V$5) -> 0 | W21: =SUMIFS(data!$G:$G,data!$C:$C,$B$13,data!$D:$D,$B$18,data!$F:$F,W$4,data!$E:$E,$B21,data!$H:$H,ПФ2026!W$5) -> -19450.436 | X21: =SUMIFS(data!$G:$G,data!$C:$C,$B$13,data!$D:$D,$B$18,data!$F:$F,W$4,data!$E:$E,$B21,data!$H:$H,ПФ2026!X$5) -> 0 | Y21: =SUMIFS(data!$G:$G,data!$C:$C,$B$13,data!$D:$D,$B$18,data!$F:$F,Y$4,data!$E:$E,$B21,data!$H:$H,ПФ2026!Y$5) -> -15836.782 | Z21: =SUMIFS(data!$G:$G,data!$C:$C,$B$13,data!$D:$D,$B$18,data!$F:$F,Y$4,data!$E:$E,$B21,data!$H:$H,ПФ2026!Z$5) -> 0 | AA21: =SUM(C21,E21,G21,I21,K21,M21,O81,O21,Q21,S21,Y21,W21,U21) -> -272658.3 | AB21: =D21+F21+H21+J21+L21+N21+P21+R21+T21+V21+X21+Z21 -> 0 | AC21: =IFERROR(AB21/AA21,0) -> 0
B22: 2160/Амортизация - мебель и прочие принадлежности | C22: =SUMIFS(data!$G:$G,data!$C:$C,$B$13,data!$D:$D,$B$18,data!$F:$F,C$4,data!$E:$E,$B22,data!$H:$H,ПФ2026!C$5) -> -40101.369 | D22: =SUMIFS(data!$G:$G,data!$C:$C,$B$13,data!$D:$D,$B$18,data!$F:$F,C$4,data!$E:$E,$B22,data!$H:$H,ПФ2026!D$5) -> 0 | E22: =SUMIFS(data!$G:$G,data!$C:$C,$B$13,data!$D:$D,$B$18,data!$F:$F,E$4,data!$E:$E,$B22,data!$H:$H,ПФ2026!E$5) -> -41062.499 | F22: =SUMIFS(data!$G:$G,data!$C:$C,$B$13,data!$D:$D,$B$18,data!$F:$F,E$4,data!$E:$E,$B22,data!$H:$H,ПФ2026!F$5) -> 0 | G22: =SUMIFS(data!$G:$G,data!$C:$C,$B$13,data!$D:$D,$B$18,data!$F:$F,G$4,data!$E:$E,$B22,data!$H:$H,ПФ2026!G$5) -> -44233.643 | H22: =SUMIFS(data!$G:$G,data!$C:$C,$B$13,data!$D:$D,$B$18,data!$F:$F,G$4,data!$E:$E,$B22,data!$H:$H,ПФ2026!H$5) -> 0 | I22: =SUMIFS(data!$G:$G,data!$C:$C,$B$13,data!$D:$D,$B$18,data!$F:$F,I$4,data!$E:$E,$B22,data!$H:$H,ПФ2026!I$5) -> -44233.643 | J22: =SUMIFS(data!$G:$G,data!$C:$C,$B$13,data!$D:$D,$B$18,data!$F:$F,I$4,data!$E:$E,$B22,data!$H:$H,ПФ2026!J$5) -> 0 | K22: =SUMIFS(data!$G:$G,data!$C:$C,$B$13,data!$D:$D,$B$18,data!$F:$F,K$4,data!$E:$E,$B22,data!$H:$H,ПФ2026!K$5) -> -45586.972 | L22: =SUMIFS(data!$G:$G,data!$C:$C,$B$13,data!$D:$D,$B$18,data!$F:$F,K$4,data!$E:$E,$B22,data!$H:$H,ПФ2026!L$5) -> 0 | M22: =SUMIFS(data!$G:$G,data!$C:$C,$B$13,data!$D:$D,$B$18,data!$F:$F,M$4,data!$E:$E,$B22,data!$H:$H,ПФ2026!M$5) -> -44543.602 | N22: =SUMIFS(data!$G:$G,data!$C:$C,$B$13,data!$D:$D,$B$18,data!$F:$F,M$4,data!$E:$E,$B22,data!$H:$H,ПФ2026!N$5) -> 0 | O22: =SUMIFS(data!$G:$G,data!$C:$C,$B$13,data!$D:$D,$B$18,data!$F:$F,O$4,data!$E:$E,$B22,data!$H:$H,ПФ2026!O$5) -> -39113.062 | P22: =SUMIFS(data!$G:$G,data!$C:$C,$B$13,data!$D:$D,$B$18,data!$F:$F,O$4,data!$E:$E,$B22,data!$H:$H,ПФ2026!P$5) -> 0 | Q22: =SUMIFS(data!$G:$G,data!$C:$C,$B$13,data!$D:$D,$B$18,data!$F:$F,Q$4,data!$E:$E,$B22,data!$H:$H,ПФ2026!Q$5) -> -32107.988 | R22: =SUMIFS(data!$G:$G,data!$C:$C,$B$13,data!$D:$D,$B$18,data!$F:$F,Q$4,data!$E:$E,$B22,data!$H:$H,ПФ2026!R$5) -> 0 | S22: =SUMIFS(data!$G:$G,data!$C:$C,$B$13,data!$D:$D,$B$18,data!$F:$F,S$4,data!$E:$E,$B22,data!$H:$H,ПФ2026!S$5) -> -80001.396 | T22: =SUMIFS(data!$G:$G,data!$C:$C,$B$13,data!$D:$D,$B$18,data!$F:$F,S$4,data!$E:$E,$B22,data!$H:$H,ПФ2026!T$5) -> 0 | U22: =SUMIFS(data!$G:$G,data!$C:$C,$B$13,data!$D:$D,$B$18,data!$F:$F,U$4,data!$E:$E,$B22,data!$H:$H,ПФ2026!U$5) -> -30347.269 | V22: =SUMIFS(data!$G:$G,data!$C:$C,$B$13,data!$D:$D,$B$18,data!$F:$F,U$4,data!$E:$E,$B22,data!$H:$H,ПФ2026!V$5) -> 0 | W22: =SUMIFS(data!$G:$G,data!$C:$C,$B$13,data!$D:$D,$B$18,data!$F:$F,W$4,data!$E:$E,$B22,data!$H:$H,ПФ2026!W$5) -> -30346.324 | X22: =SUMIFS(data!$G:$G,data!$C:$C,$B$13,data!$D:$D,$B$18,data!$F:$F,W$4,data!$E:$E,$B22,data!$H:$H,ПФ2026!X$5) -> 0 | Y22: =SUMIFS(data!$G:$G,data!$C:$C,$B$13,data!$D:$D,$B$18,data!$F:$F,Y$4,data!$E:$E,$B22,data!$H:$H,ПФ2026!Y$5) -> -24181.773 | Z22: =SUMIFS(data!$G:$G,data!$C:$C,$B$13,data!$D:$D,$B$18,data!$F:$F,Y$4,data!$E:$E,$B22,data!$H:$H,ПФ2026!Z$5) -> 0 | AA22: =SUM(C22,E22,G22,I22,K22,M22,O82,O22,Q22,S22,Y22,W22,U22) -> -495859.54 | AB22: =D22+F22+H22+J22+L22+N22+P22+R22+T22+V22+X22+Z22 -> 0 | AC22: =IFERROR(AB22/AA22,0) -> 0
B23: 2170/Амортизация - транспортные средства | C23: =SUMIFS(data!$G:$G,data!$C:$C,$B$13,data!$D:$D,$B$18,data!$F:$F,C$4,data!$E:$E,$B23,data!$H:$H,ПФ2026!C$5) -> 0 | D23: =SUMIFS(data!$G:$G,data!$C:$C,$B$13,data!$D:$D,$B$18,data!$F:$F,C$4,data!$E:$E,$B23,data!$H:$H,ПФ2026!D$5) -> 0 | E23: =SUMIFS(data!$G:$G,data!$C:$C,$B$13,data!$D:$D,$B$18,data!$F:$F,E$4,data!$E:$E,$B23,data!$H:$H,ПФ2026!E$5) -> 0 | F23: =SUMIFS(data!$G:$G,data!$C:$C,$B$13,data!$D:$D,$B$18,data!$F:$F,E$4,data!$E:$E,$B23,data!$H:$H,ПФ2026!F$5) -> 0 | G23: =SUMIFS(data!$G:$G,data!$C:$C,$B$13,data!$D:$D,$B$18,data!$F:$F,G$4,data!$E:$E,$B23,data!$H:$H,ПФ2026!G$5) -> 0 | H23: =SUMIFS(data!$G:$G,data!$C:$C,$B$13,data!$D:$D,$B$18,data!$F:$F,G$4,data!$E:$E,$B23,data!$H:$H,ПФ2026!H$5) -> 0 | I23: =SUMIFS(data!$G:$G,data!$C:$C,$B$13,data!$D:$D,$B$18,data!$F:$F,I$4,data!$E:$E,$B23,data!$H:$H,ПФ2026!I$5) -> 0 | J23: =SUMIFS(data!$G:$G,data!$C:$C,$B$13,data!$D:$D,$B$18,data!$F:$F,I$4,data!$E:$E,$B23,data!$H:$H,ПФ2026!J$5) -> 0 | K23: =SUMIFS(data!$G:$G,data!$C:$C,$B$13,data!$D:$D,$B$18,data!$F:$F,K$4,data!$E:$E,$B23,data!$H:$H,ПФ2026!K$5) -> 0 | L23: =SUMIFS(data!$G:$G,data!$C:$C,$B$13,data!$D:$D,$B$18,data!$F:$F,K$4,data!$E:$E,$B23,data!$H:$H,ПФ2026!L$5) -> 0 | M23: =SUMIFS(data!$G:$G,data!$C:$C,$B$13,data!$D:$D,$B$18,data!$F:$F,M$4,data!$E:$E,$B23,data!$H:$H,ПФ2026!M$5) -> 0 | N23: =SUMIFS(data!$G:$G,data!$C:$C,$B$13,data!$D:$D,$B$18,data!$F:$F,M$4,data!$E:$E,$B23,data!$H:$H,ПФ2026!N$5) -> 0 | O23: =SUMIFS(data!$G:$G,data!$C:$C,$B$13,data!$D:$D,$B$18,data!$F:$F,O$4,data!$E:$E,$B23,data!$H:$H,ПФ2026!O$5) -> 0 | P23: =SUMIFS(data!$G:$G,data!$C:$C,$B$13,data!$D:$D,$B$18,data!$F:$F,O$4,data!$E:$E,$B23,data!$H:$H,ПФ2026!P$5) -> 0 | Q23: =SUMIFS(data!$G:$G,data!$C:$C,$B$13,data!$D:$D,$B$18,data!$F:$F,Q$4,data!$E:$E,$B23,data!$H:$H,ПФ2026!Q$5) -> 0 | R23: =SUMIFS(data!$G:$G,data!$C:$C,$B$13,data!$D:$D,$B$18,data!$F:$F,Q$4,data!$E:$E,$B23,data!$H:$H,ПФ2026!R$5) -> 0 | S23: =SUMIFS(data!$G:$G,data!$C:$C,$B$13,data!$D:$D,$B$18,data!$F:$F,S$4,data!$E:$E,$B23,data!$H:$H,ПФ2026!S$5) -> 0 | T23: =SUMIFS(data!$G:$G,data!$C:$C,$B$13,data!$D:$D,$B$18,data!$F:$F,S$4,data!$E:$E,$B23,data!$H:$H,ПФ2026!T$5) -> 0 | U23: =SUMIFS(data!$G:$G,data!$C:$C,$B$13,data!$D:$D,$B$18,data!$F:$F,U$4,data!$E:$E,$B23,data!$H:$H,ПФ2026!U$5) -> 0 | V23: =SUMIFS(data!$G:$G,data!$C:$C,$B$13,data!$D:$D,$B$18,data!$F:$F,U$4,data!$E:$E,$B23,data!$H:$H,ПФ2026!V$5) -> 0 | W23: =SUMIFS(data!$G:$G,data!$C:$C,$B$13,data!$D:$D,$B$18,data!$F:$F,W$4,data!$E:$E,$B23,data!$H:$H,ПФ2026!W$5) -> 0 | X23: =SUMIFS(data!$G:$G,data!$C:$C,$B$13,data!$D:$D,$B$18,data!$F:$F,W$4,data!$E:$E,$B23,data!$H:$H,ПФ2026!X$5) -> 0 | Y23: =SUMIFS(data!$G:$G,data!$C:$C,$B$13,data!$D:$D,$B$18,data!$F:$F,Y$4,data!$E:$E,$B23,data!$H:$H,ПФ2026!Y$5) -> 0 | Z23: =SUMIFS(data!$G:$G,data!$C:$C,$B$13,data!$D:$D,$B$18,data!$F:$F,Y$4,data!$E:$E,$B23,data!$H:$H,ПФ2026!Z$5) -> 0 | AA23: =SUM(C23,E23,G23,I23,K23,M23,O83,O23,Q23,S23,Y23,W23,U23) -> 0 | AB23: =D23+F23+H23+J23+L23+N23+P23+R23+T23+V23+X23+Z23 -> 0 | AC23: =IFERROR(AB23/AA23,0) -> 0
B24: Расходы по ком.услуга | C24: =SUM(C25:C27) -> -1640197.4 | D24: =SUM(D25:D27) -> -1903483.3 | E24: =SUM(E25:E27) -> -2344355.5 | F24: =SUM(F25:F27) -> -2050465.1 | G24: =SUM(G25:G27) -> -1529613.3 | H24: =SUM(H25:H27) -> -2078987.8 | I24: =SUM(I25:I27) -> -2213918 | J24: =SUM(J25:J27) -> -2521758.5 | ... Z24: =SUM(Z25:Z27) -> 0 | AA24: =SUM(C24,E24,G24,I24,K24,M24,O84,O24,Q24,S24,Y24,W24,U24) -> -34831591 | AB24: =D24+F24+H24+J24+L24+N24+P24+R24+T24+V24+X24+Z24 -> -15888135 | AC24: =IFERROR(AB24/AA24,0) -> 0.45614153
B25: Вода, стоки и канализация | C25: =SUMIFS(data!$G:$G,data!$C:$C,$B$13,data!$D:$D,$B$24,data!$F:$F,C$4,data!$E:$E,$B25,data!$H:$H,ПФ2026!C$5) -> 0 | D25: =SUMIFS(data!$G:$G,data!$C:$C,$B$13,data!$D:$D,$B$24,data!$F:$F,C$4,data!$E:$E,$B25,data!$H:$H,ПФ2026!D$5) -> 0 | E25: =SUMIFS(data!$G:$G,data!$C:$C,$B$13,data!$D:$D,$B$24,data!$F:$F,E$4,data!$E:$E,$B25,data!$H:$H,ПФ2026!E$5) -> 0 | F25: =SUMIFS(data!$G:$G,data!$C:$C,$B$13,data!$D:$D,$B$24,data!$F:$F,E$4,data!$E:$E,$B25,data!$H:$H,ПФ2026!F$5) -> 0 | G25: =SUMIFS(data!$G:$G,data!$C:$C,$B$13,data!$D:$D,$B$24,data!$F:$F,G$4,data!$E:$E,$B25,data!$H:$H,ПФ2026!G$5) -> 0 | H25: =SUMIFS(data!$G:$G,data!$C:$C,$B$13,data!$D:$D,$B$24,data!$F:$F,G$4,data!$E:$E,$B25,data!$H:$H,ПФ2026!H$5) -> -6005.45 | I25: =SUMIFS(data!$G:$G,data!$C:$C,$B$13,data!$D:$D,$B$24,data!$F:$F,I$4,data!$E:$E,$B25,data!$H:$H,ПФ2026!I$5) -> 0 | J25: =SUMIFS(data!$G:$G,data!$C:$C,$B$13,data!$D:$D,$B$24,data!$F:$F,I$4,data!$E:$E,$B25,data!$H:$H,ПФ2026!J$5) -> -45562.91 | K25: =SUMIFS(data!$G:$G,data!$C:$C,$B$13,data!$D:$D,$B$24,data!$F:$F,K$4,data!$E:$E,$B25,data!$H:$H,ПФ2026!K$5) -> 0 | L25: =SUMIFS(data!$G:$G,data!$C:$C,$B$13,data!$D:$D,$B$24,data!$F:$F,K$4,data!$E:$E,$B25,data!$H:$H,ПФ2026!L$5) -> -198962.45 | M25: =SUMIFS(data!$G:$G,data!$C:$C,$B$13,data!$D:$D,$B$24,data!$F:$F,M$4,data!$E:$E,$B25,data!$H:$H,ПФ2026!M$5) -> 0 | N25: =SUMIFS(data!$G:$G,data!$C:$C,$B$13,data!$D:$D,$B$24,data!$F:$F,M$4,data!$E:$E,$B25,data!$H:$H,ПФ2026!N$5) -> -193479.25 | O25: =SUMIFS(data!$G:$G,data!$C:$C,$B$13,data!$D:$D,$B$24,data!$F:$F,O$4,data!$E:$E,$B25,data!$H:$H,ПФ2026!O$5) -> 0 | P25: =SUMIFS(data!$G:$G,data!$C:$C,$B$13,data!$D:$D,$B$24,data!$F:$F,O$4,data!$E:$E,$B25,data!$H:$H,ПФ2026!P$5) -> 0 | Q25: =SUMIFS(data!$G:$G,data!$C:$C,$B$13,data!$D:$D,$B$24,data!$F:$F,Q$4,data!$E:$E,$B25,data!$H:$H,ПФ2026!Q$5) -> 0 | R25: =SUMIFS(data!$G:$G,data!$C:$C,$B$13,data!$D:$D,$B$24,data!$F:$F,Q$4,data!$E:$E,$B25,data!$H:$H,ПФ2026!R$5) -> 0 | S25: =SUMIFS(data!$G:$G,data!$C:$C,$B$13,data!$D:$D,$B$24,data!$F:$F,S$4,data!$E:$E,$B25,data!$H:$H,ПФ2026!S$5) -> 0 | T25: =SUMIFS(data!$G:$G,data!$C:$C,$B$13,data!$D:$D,$B$24,data!$F:$F,S$4,data!$E:$E,$B25,data!$H:$H,ПФ2026!T$5) -> 0 | U25: =SUMIFS(data!$G:$G,data!$C:$C,$B$13,data!$D:$D,$B$24,data!$F:$F,U$4,data!$E:$E,$B25,data!$H:$H,ПФ2026!U$5) -> 0 | V25: =SUMIFS(data!$G:$G,data!$C:$C,$B$13,data!$D:$D,$B$24,data!$F:$F,U$4,data!$E:$E,$B25,data!$H:$H,ПФ2026!V$5) -> 0 | W25: =SUMIFS(data!$G:$G,data!$C:$C,$B$13,data!$D:$D,$B$24,data!$F:$F,W$4,data!$E:$E,$B25,data!$H:$H,ПФ2026!W$5) -> 0 | X25: =SUMIFS(data!$G:$G,data!$C:$C,$B$13,data!$D:$D,$B$24,data!$F:$F,W$4,data!$E:$E,$B25,data!$H:$H,ПФ2026!X$5) -> 0 | Y25: =SUMIFS(data!$G:$G,data!$C:$C,$B$13,data!$D:$D,$B$24,data!$F:$F,Y$4,data!$E:$E,$B25,data!$H:$H,ПФ2026!Y$5) -> 0 | Z25: =SUMIFS(data!$G:$G,data!$C:$C,$B$13,data!$D:$D,$B$24,data!$F:$F,Y$4,data!$E:$E,$B25,data!$H:$H,ПФ2026!Z$5) -> 0 | AA25: =SUM(C25,E25,G25,I25,K25,M25,O85,O25,Q25,S25,Y25,W25,U25) -> -515000 | AB25: =D25+F25+H25+J25+L25+N25+P25+R25+T25+V25+X25+Z25 -> -444010.06 | AC25: =IFERROR(AB25/AA25,0) -> 0.86215546
B26: Природный газ | C26: =SUMIFS(data!$G:$G,data!$C:$C,$B$13,data!$D:$D,$B$24,data!$F:$F,C$4,data!$E:$E,$B26,data!$H:$H,ПФ2026!C$5) -> 8869.4441 | D26: =SUMIFS(data!$G:$G,data!$C:$C,$B$13,data!$D:$D,$B$24,data!$F:$F,C$4,data!$E:$E,$B26,data!$H:$H,ПФ2026!D$5) -> -40536.91 | E26: =SUMIFS(data!$G:$G,data!$C:$C,$B$13,data!$D:$D,$B$24,data!$F:$F,E$4,data!$E:$E,$B26,data!$H:$H,ПФ2026!E$5) -> -71501.308 | F26: =SUMIFS(data!$G:$G,data!$C:$C,$B$13,data!$D:$D,$B$24,data!$F:$F,E$4,data!$E:$E,$B26,data!$H:$H,ПФ2026!F$5) -> 0 | G26: =SUMIFS(data!$G:$G,data!$C:$C,$B$13,data!$D:$D,$B$24,data!$F:$F,G$4,data!$E:$E,$B26,data!$H:$H,ПФ2026!G$5) -> -58842.169 | H26: =SUMIFS(data!$G:$G,data!$C:$C,$B$13,data!$D:$D,$B$24,data!$F:$F,G$4,data!$E:$E,$B26,data!$H:$H,ПФ2026!H$5) -> -56712.54 | I26: =SUMIFS(data!$G:$G,data!$C:$C,$B$13,data!$D:$D,$B$24,data!$F:$F,I$4,data!$E:$E,$B26,data!$H:$H,ПФ2026!I$5) -> -97058.97 | J26: =SUMIFS(data!$G:$G,data!$C:$C,$B$13,data!$D:$D,$B$24,data!$F:$F,I$4,data!$E:$E,$B26,data!$H:$H,ПФ2026!J$5) -> -791.52 | K26: =SUMIFS(data!$G:$G,data!$C:$C,$B$13,data!$D:$D,$B$24,data!$F:$F,K$4,data!$E:$E,$B26,data!$H:$H,ПФ2026!K$5) -> -107360.64 | L26: =SUMIFS(data!$G:$G,data!$C:$C,$B$13,data!$D:$D,$B$24,data!$F:$F,K$4,data!$E:$E,$B26,data!$H:$H,ПФ2026!L$5) -> -300800.17 | M26: =SUMIFS(data!$G:$G,data!$C:$C,$B$13,data!$D:$D,$B$24,data!$F:$F,M$4,data!$E:$E,$B26,data!$H:$H,ПФ2026!M$5) -> -121121.4 | N26: =SUMIFS(data!$G:$G,data!$C:$C,$B$13,data!$D:$D,$B$24,data!$F:$F,M$4,data!$E:$E,$B26,data!$H:$H,ПФ2026!N$5) -> -144242.05 | O26: =SUMIFS(data!$G:$G,data!$C:$C,$B$13,data!$D:$D,$B$24,data!$F:$F,O$4,data!$E:$E,$B26,data!$H:$H,ПФ2026!O$5) -> -120654.42 | P26: =SUMIFS(data!$G:$G,data!$C:$C,$B$13,data!$D:$D,$B$24,data!$F:$F,O$4,data!$E:$E,$B26,data!$H:$H,ПФ2026!P$5) -> 0 | Q26: =SUMIFS(data!$G:$G,data!$C:$C,$B$13,data!$D:$D,$B$24,data!$F:$F,Q$4,data!$E:$E,$B26,data!$H:$H,ПФ2026!Q$5) -> -85538.91 | R26: =SUMIFS(data!$G:$G,data!$C:$C,$B$13,data!$D:$D,$B$24,data!$F:$F,Q$4,data!$E:$E,$B26,data!$H:$H,ПФ2026!R$5) -> 0 | S26: =SUMIFS(data!$G:$G,data!$C:$C,$B$13,data!$D:$D,$B$24,data!$F:$F,S$4,data!$E:$E,$B26,data!$H:$H,ПФ2026!S$5) -> -80237.826 | T26: =SUMIFS(data!$G:$G,data!$C:$C,$B$13,data!$D:$D,$B$24,data!$F:$F,S$4,data!$E:$E,$B26,data!$H:$H,ПФ2026!T$5) -> 0 | U26: =SUMIFS(data!$G:$G,data!$C:$C,$B$13,data!$D:$D,$B$24,data!$F:$F,U$4,data!$E:$E,$B26,data!$H:$H,ПФ2026!U$5) -> -68738.536 | V26: =SUMIFS(data!$G:$G,data!$C:$C,$B$13,data!$D:$D,$B$24,data!$F:$F,U$4,data!$E:$E,$B26,data!$H:$H,ПФ2026!V$5) -> 0 | W26: =SUMIFS(data!$G:$G,data!$C:$C,$B$13,data!$D:$D,$B$24,data!$F:$F,W$4,data!$E:$E,$B26,data!$H:$H,ПФ2026!W$5) -> -65741.236 | X26: =SUMIFS(data!$G:$G,data!$C:$C,$B$13,data!$D:$D,$B$24,data!$F:$F,W$4,data!$E:$E,$B26,data!$H:$H,ПФ2026!X$5) -> 0 | Y26: =SUMIFS(data!$G:$G,data!$C:$C,$B$13,data!$D:$D,$B$24,data!$F:$F,Y$4,data!$E:$E,$B26,data!$H:$H,ПФ2026!Y$5) -> -66013.494 | Z26: =SUMIFS(data!$G:$G,data!$C:$C,$B$13,data!$D:$D,$B$24,data!$F:$F,Y$4,data!$E:$E,$B26,data!$H:$H,ПФ2026!Z$5) -> 0 | AA26: =SUM(C26,E26,G26,I26,K26,M26,O86,O26,Q26,S26,Y26,W26,U26) -> -993939.47 | AB26: =D26+F26+H26+J26+L26+N26+P26+R26+T26+V26+X26+Z26 -> -543083.19 | AC26: =IFERROR(AB26/AA26,0) -> 0.54639463
B27: Электроэнергия | C27: =SUMIFS(data!$G:$G,data!$C:$C,$B$13,data!$D:$D,$B$24,data!$F:$F,C$4,data!$E:$E,$B27,data!$H:$H,ПФ2026!C$5) -> -1649066.8 | D27: =SUMIFS(data!$G:$G,data!$C:$C,$B$13,data!$D:$D,$B$24,data!$F:$F,C$4,data!$E:$E,$B27,data!$H:$H,ПФ2026!D$5) -> -1862946.4 | E27: =SUMIFS(data!$G:$G,data!$C:$C,$B$13,data!$D:$D,$B$24,data!$F:$F,E$4,data!$E:$E,$B27,data!$H:$H,ПФ2026!E$5) -> -2272854.2 | F27: =SUMIFS(data!$G:$G,data!$C:$C,$B$13,data!$D:$D,$B$24,data!$F:$F,E$4,data!$E:$E,$B27,data!$H:$H,ПФ2026!F$5) -> -2050465.1 | G27: =SUMIFS(data!$G:$G,data!$C:$C,$B$13,data!$D:$D,$B$24,data!$F:$F,G$4,data!$E:$E,$B27,data!$H:$H,ПФ2026!G$5) -> -1470771.1 | H27: =SUMIFS(data!$G:$G,data!$C:$C,$B$13,data!$D:$D,$B$24,data!$F:$F,G$4,data!$E:$E,$B27,data!$H:$H,ПФ2026!H$5) -> -2016269.8 | I27: =SUMIFS(data!$G:$G,data!$C:$C,$B$13,data!$D:$D,$B$24,data!$F:$F,I$4,data!$E:$E,$B27,data!$H:$H,ПФ2026!I$5) -> -2116859.1 | J27: =SUMIFS(data!$G:$G,data!$C:$C,$B$13,data!$D:$D,$B$24,data!$F:$F,I$4,data!$E:$E,$B27,data!$H:$H,ПФ2026!J$5) -> -2475404 | K27: =SUMIFS(data!$G:$G,data!$C:$C,$B$13,data!$D:$D,$B$24,data!$F:$F,K$4,data!$E:$E,$B27,data!$H:$H,ПФ2026!K$5) -> -2563563.7 | L27: =SUMIFS(data!$G:$G,data!$C:$C,$B$13,data!$D:$D,$B$24,data!$F:$F,K$4,data!$E:$E,$B27,data!$H:$H,ПФ2026!L$5) -> -2906727.6 | M27: =SUMIFS(data!$G:$G,data!$C:$C,$B$13,data!$D:$D,$B$24,data!$F:$F,M$4,data!$E:$E,$B27,data!$H:$H,ПФ2026!M$5) -> -2806475 | N27: =SUMIFS(data!$G:$G,data!$C:$C,$B$13,data!$D:$D,$B$24,data!$F:$F,M$4,data!$E:$E,$B27,data!$H:$H,ПФ2026!N$5) -> -3589229.1 | O27: =SUMIFS(data!$G:$G,data!$C:$C,$B$13,data!$D:$D,$B$24,data!$F:$F,O$4,data!$E:$E,$B27,data!$H:$H,ПФ2026!O$5) -> -2985621.2 | P27: =SUMIFS(data!$G:$G,data!$C:$C,$B$13,data!$D:$D,$B$24,data!$F:$F,O$4,data!$E:$E,$B27,data!$H:$H,ПФ2026!P$5) -> 0 | Q27: =SUMIFS(data!$G:$G,data!$C:$C,$B$13,data!$D:$D,$B$24,data!$F:$F,Q$4,data!$E:$E,$B27,data!$H:$H,ПФ2026!Q$5) -> -3012850.1 | R27: =SUMIFS(data!$G:$G,data!$C:$C,$B$13,data!$D:$D,$B$24,data!$F:$F,Q$4,data!$E:$E,$B27,data!$H:$H,ПФ2026!R$5) -> 0 | S27: =SUMIFS(data!$G:$G,data!$C:$C,$B$13,data!$D:$D,$B$24,data!$F:$F,S$4,data!$E:$E,$B27,data!$H:$H,ПФ2026!S$5) -> -4438331.4 | T27: =SUMIFS(data!$G:$G,data!$C:$C,$B$13,data!$D:$D,$B$24,data!$F:$F,S$4,data!$E:$E,$B27,data!$H:$H,ПФ2026!T$5) -> 0 | U27: =SUMIFS(data!$G:$G,data!$C:$C,$B$13,data!$D:$D,$B$24,data!$F:$F,U$4,data!$E:$E,$B27,data!$H:$H,ПФ2026!U$5) -> -3439263.7 | V27: =SUMIFS(data!$G:$G,data!$C:$C,$B$13,data!$D:$D,$B$24,data!$F:$F,U$4,data!$E:$E,$B27,data!$H:$H,ПФ2026!V$5) -> 0 | W27: =SUMIFS(data!$G:$G,data!$C:$C,$B$13,data!$D:$D,$B$24,data!$F:$F,W$4,data!$E:$E,$B27,data!$H:$H,ПФ2026!W$5) -> -3643003.1 | X27: =SUMIFS(data!$G:$G,data!$C:$C,$B$13,data!$D:$D,$B$24,data!$F:$F,W$4,data!$E:$E,$B27,data!$H:$H,ПФ2026!X$5) -> 0 | Y27: =SUMIFS(data!$G:$G,data!$C:$C,$B$13,data!$D:$D,$B$24,data!$F:$F,Y$4,data!$E:$E,$B27,data!$H:$H,ПФ2026!Y$5) -> -3498992.1 | Z27: =SUMIFS(data!$G:$G,data!$C:$C,$B$13,data!$D:$D,$B$24,data!$F:$F,Y$4,data!$E:$E,$B27,data!$H:$H,ПФ2026!Z$5) -> 0 | AA27: =SUM(C27,E27,G27,I27,K27,M27,O87,O27,Q27,S27,Y27,W27,U27) -> -34052051 | AB27: =D27+F27+H27+J27+L27+N27+P27+R27+T27+V27+X27+Z27 -> -14901042 | AC27: =IFERROR(AB27/AA27,0) -> 0.43759602
B28: Расходы на дезинфицирующие средства | C28: =SUM(C29) -> -755239.2 | D28: =SUM(D29) -> -829855.97 | E28: =SUM(E29) -> -690216 | F28: =SUM(F29) -> -781337.17 | G28: =SUM(G29) -> -860728 | H28: =SUM(H29) -> -1546326.1 | I28: =SUM(I29) -> -1067128 | J28: =SUM(J29) -> -1518675.3 | ... Z28: =SUM(Z29) -> 0 | AA28: =SUM(C28,E28,G28,I28,K28,M28,O88,O28,Q28,S28,Y28,W28,U28) -> -11660431 | AB28: =D28+F28+H28+J28+L28+N28+P28+R28+T28+V28+X28+Z28 -> -8940634.6 | AC28: =IFERROR(AB28/AA28,0) -> 0.76674991
B29: Расходы на дезинфицирующие средства | C29: =SUMIFS(data!$G:$G,data!$C:$C,$B$13,data!$D:$D,$B$28,data!$F:$F,C$4,data!$E:$E,$B29,data!$H:$H,ПФ2026!C$5) -> -755239.2 | D29: =SUMIFS(data!$G:$G,data!$C:$C,$B$13,data!$D:$D,$B$28,data!$F:$F,C$4,data!$E:$E,$B29,data!$H:$H,ПФ2026!D$5) -> -829855.97 | E29: =SUMIFS(data!$G:$G,data!$C:$C,$B$13,data!$D:$D,$B$28,data!$F:$F,E$4,data!$E:$E,$B29,data!$H:$H,ПФ2026!E$5) -> -690216 | F29: =SUMIFS(data!$G:$G,data!$C:$C,$B$13,data!$D:$D,$B$28,data!$F:$F,E$4,data!$E:$E,$B29,data!$H:$H,ПФ2026!F$5) -> -781337.17 | G29: =SUMIFS(data!$G:$G,data!$C:$C,$B$13,data!$D:$D,$B$28,data!$F:$F,G$4,data!$E:$E,$B29,data!$H:$H,ПФ2026!G$5) -> -860728 | H29: =SUMIFS(data!$G:$G,data!$C:$C,$B$13,data!$D:$D,$B$28,data!$F:$F,G$4,data!$E:$E,$B29,data!$H:$H,ПФ2026!H$5) -> -1546326.1 | I29: =SUMIFS(data!$G:$G,data!$C:$C,$B$13,data!$D:$D,$B$28,data!$F:$F,I$4,data!$E:$E,$B29,data!$H:$H,ПФ2026!I$5) -> -1067128 | J29: =SUMIFS(data!$G:$G,data!$C:$C,$B$13,data!$D:$D,$B$28,data!$F:$F,I$4,data!$E:$E,$B29,data!$H:$H,ПФ2026!J$5) -> -1518675.3 | K29: =SUMIFS(data!$G:$G,data!$C:$C,$B$13,data!$D:$D,$B$28,data!$F:$F,K$4,data!$E:$E,$B29,data!$H:$H,ПФ2026!K$5) -> -1065228 | L29: =SUMIFS(data!$G:$G,data!$C:$C,$B$13,data!$D:$D,$B$28,data!$F:$F,K$4,data!$E:$E,$B29,data!$H:$H,ПФ2026!L$5) -> -1815898.4 | M29: =SUMIFS(data!$G:$G,data!$C:$C,$B$13,data!$D:$D,$B$28,data!$F:$F,M$4,data!$E:$E,$B29,data!$H:$H,ПФ2026!M$5) -> -1138748 | N29: =SUMIFS(data!$G:$G,data!$C:$C,$B$13,data!$D:$D,$B$28,data!$F:$F,M$4,data!$E:$E,$B29,data!$H:$H,ПФ2026!N$5) -> -2448541.7 | O29: =SUMIFS(data!$G:$G,data!$C:$C,$B$13,data!$D:$D,$B$28,data!$F:$F,O$4,data!$E:$E,$B29,data!$H:$H,ПФ2026!O$5) -> -1274198.4 | P29: =SUMIFS(data!$G:$G,data!$C:$C,$B$13,data!$D:$D,$B$28,data!$F:$F,O$4,data!$E:$E,$B29,data!$H:$H,ПФ2026!P$5) -> 0 | Q29: =SUMIFS(data!$G:$G,data!$C:$C,$B$13,data!$D:$D,$B$28,data!$F:$F,Q$4,data!$E:$E,$B29,data!$H:$H,ПФ2026!Q$5) -> -1221966.4 | R29: =SUMIFS(data!$G:$G,data!$C:$C,$B$13,data!$D:$D,$B$28,data!$F:$F,Q$4,data!$E:$E,$B29,data!$H:$H,ПФ2026!R$5) -> 0 | S29: =SUMIFS(data!$G:$G,data!$C:$C,$B$13,data!$D:$D,$B$28,data!$F:$F,S$4,data!$E:$E,$B29,data!$H:$H,ПФ2026!S$5) -> -1154674.4 | T29: =SUMIFS(data!$G:$G,data!$C:$C,$B$13,data!$D:$D,$B$28,data!$F:$F,S$4,data!$E:$E,$B29,data!$H:$H,ПФ2026!T$5) -> 0 | U29: =SUMIFS(data!$G:$G,data!$C:$C,$B$13,data!$D:$D,$B$28,data!$F:$F,U$4,data!$E:$E,$B29,data!$H:$H,ПФ2026!U$5) -> -894862.4 | V29: =SUMIFS(data!$G:$G,data!$C:$C,$B$13,data!$D:$D,$B$28,data!$F:$F,U$4,data!$E:$E,$B29,data!$H:$H,ПФ2026!V$5) -> 0 | W29: =SUMIFS(data!$G:$G,data!$C:$C,$B$13,data!$D:$D,$B$28,data!$F:$F,W$4,data!$E:$E,$B29,data!$H:$H,ПФ2026!W$5) -> -771915.2 | X29: =SUMIFS(data!$G:$G,data!$C:$C,$B$13,data!$D:$D,$B$28,data!$F:$F,W$4,data!$E:$E,$B29,data!$H:$H,ПФ2026!X$5) -> 0 | Y29: =SUMIFS(data!$G:$G,data!$C:$C,$B$13,data!$D:$D,$B$28,data!$F:$F,Y$4,data!$E:$E,$B29,data!$H:$H,ПФ2026!Y$5) -> -765527.2 | Z29: =SUMIFS(data!$G:$G,data!$C:$C,$B$13,data!$D:$D,$B$28,data!$F:$F,Y$4,data!$E:$E,$B29,data!$H:$H,ПФ2026!Z$5) -> 0 | AA29: =SUM(C29,E29,G29,I29,K29,M29,O91,O29,Q29,S29) -> -9228126.4 | AB29: =SUM(D29,F29,H29,J29,L29,N29,P91,P29,R29,T29) -> -8940634.6 | AC29: =IFERROR(AB29/AA29,0) -> 0.96884613
B30: Операционные расходы | C30: =SUM(C31,C78,C159,C235,C357,C594,C668,C691,) -> -1.3654275e+08 | D30: =SUM(D31,D78,D159,D235,D357,D594,D668,D691,) -> -1.3009556e+08 | E30: =SUM(E31,E78,E159,E235,E357,E594,E668,E691,) -> -1.4150044e+08 | F30: =SUM(F31,F78,F159,F235,F357,F594,F668,F691,) -> -1.3647242e+08 | G30: =SUM(G31,G78,G159,G235,G357,G594,G668,G691,) -> -1.9463922e+08 | H30: =SUM(H31,H78,H159,H235,H357,H594,H668,H691,) -> -1.6824038e+08 | I30: =SUM(I31,I78,I159,I235,I357,I594,I668,I691,) -> -2.3311898e+08 | J30: =SUM(J31,J78,J159,J235,J357,J594,J668,J691,) -> -2.1604847e+08 | ... Z30: =SUM(Z31,Z78,Z159,Z235,Z357,Z594,Z668,Z691,) -> 0 | AA30: =C30+E30+G30+I30+K30+M30+O30+Q30+S30+U30+W30+Y30 -> -2.5481857e+09 | AB30: =D30+F30+H30+J30+L30+N30+P30+R30+T30+V30+X30+Z30 -> -1.1804129e+09 | AC30: =IFERROR(AB30/AA30,0) -> 0.46323662
B31: Общие расходы | C31: =SUM(C32,C34,C36,C38,C41,C47,C58,C61) -> -49140853 | D31: =SUM(D32,D34,D36,D38,D41,D47,D58,D61) -> -54431423 | E31: =SUM(E32,E34,E36,E38,E41,E47,E58,E61) -> -48052936 | F31: =SUM(F32,F34,F36,F38,F41,F47,F58,F61) -> -58070430 | G31: =SUM(G32,G34,G36,G38,G41,G47,G58,G61) -> -61513948 | H31: =SUM(H32,H34,H36,H38,H41,H47,H58,H61) -> -71693878 | I31: =SUM(I32,I34,I36,I38,I41,I47,I58,I61) -> -80586352 | J31: =SUM(J32,J34,J36,J38,J41,J47,J58,J61) -> -95987840 | ... Z31: =SUM(Z32,Z34,Z36,Z38,Z41,Z47,Z58,Z61) -> 0 | AA31: =SUM(C31,E31,G31,I31,K31,M31,O93,O31,Q31,S31,U31,W31,Y31) -> -8.2417626e+08 | AB31: =SUM(D31,F31,H31,J31,L31,N31,P93,P31,R31,T31,V31,X31,Z31) -> -4.9482277e+08 | AC31: =IFERROR(AB31/AA31,0) -> 0.60038465
B32: Расходы на дезинфицирующие средства | C32: =SUM(C33) -> -19420 | D32: =SUM(D33) -> 0 | E32: =SUM(E33) -> -18280 | F32: =SUM(F33) -> 0 | G32: =SUM(G33) -> -26284 | H32: =SUM(H33) -> 0 | I32: =SUM(I33) -> -19140 | J32: =SUM(J33) -> 0 | ... Z32: =SUM(Z33) -> 0 | AA32: =SUM(C32,E32,G32,I32,K32,M32,O92,O32,Q32,S32,Y32,W32,U32) -> -256596 | AB32: =D32+F32+H32+J32+L32+N32+P32+R32+T32+V32+X32+Z32 -> 0 | AC32: =IFERROR(AB32/AA32,0) -> 0
B33: Расходы на дезинфицирующие средства | C33: =SUMIFS(data!$G:$G,data!$C:$C,$B$31,data!$D:$D,$B$32,data!$F:$F,C$4,data!$E:$E,$B33,data!$H:$H,ПФ2026!C$5) -> -19420 | D33: =SUMIFS(data!$G:$G,data!$C:$C,$B$31,data!$D:$D,$B$32,data!$F:$F,C$4,data!$E:$E,$B33,data!$H:$H,ПФ2026!D$5) -> 0 | E33: =SUMIFS(data!$G:$G,data!$C:$C,$B$31,data!$D:$D,$B$32,data!$F:$F,E$4,data!$E:$E,$B33,data!$H:$H,ПФ2026!E$5) -> -18280 | F33: =SUMIFS(data!$G:$G,data!$C:$C,$B$31,data!$D:$D,$B$32,data!$F:$F,E$4,data!$E:$E,$B33,data!$H:$H,ПФ2026!F$5) -> 0 | G33: =SUMIFS(data!$G:$G,data!$C:$C,$B$31,data!$D:$D,$B$32,data!$F:$F,G$4,data!$E:$E,$B33,data!$H:$H,ПФ2026!G$5) -> -26284 | H33: =SUMIFS(data!$G:$G,data!$C:$C,$B$31,data!$D:$D,$B$32,data!$F:$F,G$4,data!$E:$E,$B33,data!$H:$H,ПФ2026!H$5) -> 0 | I33: =SUMIFS(data!$G:$G,data!$C:$C,$B$31,data!$D:$D,$B$32,data!$F:$F,I$4,data!$E:$E,$B33,data!$H:$H,ПФ2026!I$5) -> -19140 | J33: =SUMIFS(data!$G:$G,data!$C:$C,$B$31,data!$D:$D,$B$32,data!$F:$F,I$4,data!$E:$E,$B33,data!$H:$H,ПФ2026!J$5) -> 0 | K33: =SUMIFS(data!$G:$G,data!$C:$C,$B$31,data!$D:$D,$B$32,data!$F:$F,K$4,data!$E:$E,$B33,data!$H:$H,ПФ2026!K$5) -> -19140 | L33: =SUMIFS(data!$G:$G,data!$C:$C,$B$31,data!$D:$D,$B$32,data!$F:$F,K$4,data!$E:$E,$B33,data!$H:$H,ПФ2026!L$5) -> 0 | M33: =SUMIFS(data!$G:$G,data!$C:$C,$B$31,data!$D:$D,$B$32,data!$F:$F,M$4,data!$E:$E,$B33,data!$H:$H,ПФ2026!M$5) -> -18860 | N33: =SUMIFS(data!$G:$G,data!$C:$C,$B$31,data!$D:$D,$B$32,data!$F:$F,M$4,data!$E:$E,$B33,data!$H:$H,ПФ2026!N$5) -> 0 | O33: =SUMIFS(data!$G:$G,data!$C:$C,$B$31,data!$D:$D,$B$32,data!$F:$F,O$4,data!$E:$E,$B33,data!$H:$H,ПФ2026!O$5) -> -21036 | P33: =SUMIFS(data!$G:$G,data!$C:$C,$B$31,data!$D:$D,$B$32,data!$F:$F,O$4,data!$E:$E,$B33,data!$H:$H,ПФ2026!P$5) -> 0 | Q33: =SUMIFS(data!$G:$G,data!$C:$C,$B$31,data!$D:$D,$B$32,data!$F:$F,Q$4,data!$E:$E,$B33,data!$H:$H,ПФ2026!Q$5) -> -20728 | R33: =SUMIFS(data!$G:$G,data!$C:$C,$B$31,data!$D:$D,$B$32,data!$F:$F,Q$4,data!$E:$E,$B33,data!$H:$H,ПФ2026!R$5) -> 0 | S33: =SUMIFS(data!$G:$G,data!$C:$C,$B$31,data!$D:$D,$B$32,data!$F:$F,S$4,data!$E:$E,$B33,data!$H:$H,ПФ2026!S$5) -> -22456 | T33: =SUMIFS(data!$G:$G,data!$C:$C,$B$31,data!$D:$D,$B$32,data!$F:$F,S$4,data!$E:$E,$B33,data!$H:$H,ПФ2026!T$5) -> 0 | U33: =SUMIFS(data!$G:$G,data!$C:$C,$B$31,data!$D:$D,$B$32,data!$F:$F,U$4,data!$E:$E,$B33,data!$H:$H,ПФ2026!U$5) -> -20416 | V33: =SUMIFS(data!$G:$G,data!$C:$C,$B$31,data!$D:$D,$B$32,data!$F:$F,U$4,data!$E:$E,$B33,data!$H:$H,ПФ2026!V$5) -> 0 | W33: =SUMIFS(data!$G:$G,data!$C:$C,$B$31,data!$D:$D,$B$32,data!$F:$F,W$4,data!$E:$E,$B33,data!$H:$H,ПФ2026!W$5) -> -20728 | X33: =SUMIFS(data!$G:$G,data!$C:$C,$B$31,data!$D:$D,$B$32,data!$F:$F,W$4,data!$E:$E,$B33,data!$H:$H,ПФ2026!X$5) -> 0 | Y33: =SUMIFS(data!$G:$G,data!$C:$C,$B$31,data!$D:$D,$B$32,data!$F:$F,Y$4,data!$E:$E,$B33,data!$H:$H,ПФ2026!Y$5) -> -20108 | Z33: =SUMIFS(data!$G:$G,data!$C:$C,$B$31,data!$D:$D,$B$32,data!$F:$F,Y$4,data!$E:$E,$B33,data!$H:$H,ПФ2026!Z$5) -> 0 | AA33: =SUM(C33,E33,G33,I33,K33,M33,O93,O33,Q33,S33,Y33,W33,U33) -> -246596 | AB33: =D33+F33+H33+J33+L33+N33+P33+R33+T33+V33+X33+Z33 -> 0 | AC33: =IFERROR(AB33/AA33,0) -> 0
B34: Расходы на канц.товары | C34: =SUM(C35) -> -386654.4 | D34: =SUM(D35) -> -298410.7 | E34: =SUM(E35) -> -300055.8 | F34: =SUM(F35) -> -205004.86 | G34: =SUM(G35) -> -272128.8 | H34: =SUM(H35) -> -224047.56 | I34: =SUM(I35) -> -243858 | J34: =SUM(J35) -> -458591.15 | ... Z34: =SUM(Z35) -> 0 | AA34: =SUM(C34,E34,G34,I34,K34,M34,O94,O34,Q34,S34,Y34,W34,U34) -> -3208938.5 | AB34: =D34+F34+H34+J34+L34+N34+P34+R34+T34+V34+X34+Z34 -> -2046078 | AC34: =IFERROR(AB34/AA34,0) -> 0.63761833
B35: Расходы на канц.товары | C35: =SUMIFS(data!$G:$G,data!$C:$C,$B$31,data!$D:$D,$B$34,data!$F:$F,C$4,data!$E:$E,$B35,data!$H:$H,ПФ2026!C$5) -> -386654.4 | D35: =SUMIFS(data!$G:$G,data!$C:$C,$B$31,data!$D:$D,$B$34,data!$F:$F,C$4,data!$E:$E,$B35,data!$H:$H,ПФ2026!D$5) -> -298410.7 | E35: =SUMIFS(data!$G:$G,data!$C:$C,$B$31,data!$D:$D,$B$34,data!$F:$F,E$4,data!$E:$E,$B35,data!$H:$H,ПФ2026!E$5) -> -300055.8 | F35: =SUMIFS(data!$G:$G,data!$C:$C,$B$31,data!$D:$D,$B$34,data!$F:$F,E$4,data!$E:$E,$B35,data!$H:$H,ПФ2026!F$5) -> -205004.86 | G35: =SUMIFS(data!$G:$G,data!$C:$C,$B$31,data!$D:$D,$B$34,data!$F:$F,G$4,data!$E:$E,$B35,data!$H:$H,ПФ2026!G$5) -> -272128.8 | H35: =SUMIFS(data!$G:$G,data!$C:$C,$B$31,data!$D:$D,$B$34,data!$F:$F,G$4,data!$E:$E,$B35,data!$H:$H,ПФ2026!H$5) -> -224047.56 | I35: =SUMIFS(data!$G:$G,data!$C:$C,$B$31,data!$D:$D,$B$34,data!$F:$F,I$4,data!$E:$E,$B35,data!$H:$H,ПФ2026!I$5) -> -243858 | J35: =SUMIFS(data!$G:$G,data!$C:$C,$B$31,data!$D:$D,$B$34,data!$F:$F,I$4,data!$E:$E,$B35,data!$H:$H,ПФ2026!J$5) -> -458591.15 | K35: =SUMIFS(data!$G:$G,data!$C:$C,$B$31,data!$D:$D,$B$34,data!$F:$F,K$4,data!$E:$E,$B35,data!$H:$H,ПФ2026!K$5) -> -265827.6 | L35: =SUMIFS(data!$G:$G,data!$C:$C,$B$31,data!$D:$D,$B$34,data!$F:$F,K$4,data!$E:$E,$B35,data!$H:$H,ПФ2026!L$5) -> -594993.14 | M35: =SUMIFS(data!$G:$G,data!$C:$C,$B$31,data!$D:$D,$B$34,data!$F:$F,M$4,data!$E:$E,$B35,data!$H:$H,ПФ2026!M$5) -> -271251 | N35: =SUMIFS(data!$G:$G,data!$C:$C,$B$31,data!$D:$D,$B$34,data!$F:$F,M$4,data!$E:$E,$B35,data!$H:$H,ПФ2026!N$5) -> -265030.57 | O35: =SUMIFS(data!$G:$G,data!$C:$C,$B$31,data!$D:$D,$B$34,data!$F:$F,O$4,data!$E:$E,$B35,data!$H:$H,ПФ2026!O$5) -> -264525.72 | P35: =SUMIFS(data!$G:$G,data!$C:$C,$B$31,data!$D:$D,$B$34,data!$F:$F,O$4,data!$E:$E,$B35,data!$H:$H,ПФ2026!P$5) -> 0 | Q35: =SUMIFS(data!$G:$G,data!$C:$C,$B$31,data!$D:$D,$B$34,data!$F:$F,Q$4,data!$E:$E,$B35,data!$H:$H,ПФ2026!Q$5) -> -262042.86 | R35: =SUMIFS(data!$G:$G,data!$C:$C,$B$31,data!$D:$D,$B$34,data!$F:$F,Q$4,data!$E:$E,$B35,data!$H:$H,ПФ2026!R$5) -> 0 | S35: =SUMIFS(data!$G:$G,data!$C:$C,$B$31,data!$D:$D,$B$34,data!$F:$F,S$4,data!$E:$E,$B35,data!$H:$H,ПФ2026!S$5) -> -242105.94 | T35: =SUMIFS(data!$G:$G,data!$C:$C,$B$31,data!$D:$D,$B$34,data!$F:$F,S$4,data!$E:$E,$B35,data!$H:$H,ПФ2026!T$5) -> 0 | U35: =SUMIFS(data!$G:$G,data!$C:$C,$B$31,data!$D:$D,$B$34,data!$F:$F,U$4,data!$E:$E,$B35,data!$H:$H,ПФ2026!U$5) -> -240402.78 | V35: =SUMIFS(data!$G:$G,data!$C:$C,$B$31,data!$D:$D,$B$34,data!$F:$F,U$4,data!$E:$E,$B35,data!$H:$H,ПФ2026!V$5) -> 0 | W35: =SUMIFS(data!$G:$G,data!$C:$C,$B$31,data!$D:$D,$B$34,data!$F:$F,W$4,data!$E:$E,$B35,data!$H:$H,ПФ2026!W$5) -> -231930.06 | X35: =SUMIFS(data!$G:$G,data!$C:$C,$B$31,data!$D:$D,$B$34,data!$F:$F,W$4,data!$E:$E,$B35,data!$H:$H,ПФ2026!X$5) -> 0 | Y35: =SUMIFS(data!$G:$G,data!$C:$C,$B$31,data!$D:$D,$B$34,data!$F:$F,Y$4,data!$E:$E,$B35,data!$H:$H,ПФ2026!Y$5) -> -228155.52 | Z35: =SUMIFS(data!$G:$G,data!$C:$C,$B$31,data!$D:$D,$B$34,data!$F:$F,Y$4,data!$E:$E,$B35,data!$H:$H,ПФ2026!Z$5) -> 0 | AA35: =SUM(C35,E35,G35,I35,K35,M35,O95,O35,Q35,S35,Y35,W35,U35) -> -3208938.5 | AB35: =D35+F35+H35+J35+L35+N35+P35+R35+T35+V35+X35+Z35 -> -2046078 | AC35: =IFERROR(AB35/AA35,0) -> 0.63761833
B36: Расходы на мыломоющие средства | C36: =SUM(C37:C37) -> -355301.4 | D36: =SUM(D37:D37) -> -406834.75 | E36: =SUM(E37:E37) -> -367840.2 | F36: =SUM(F37:F37) -> -572940.93 | G36: =SUM(G37:G37) -> -439411.8 | H36: =SUM(H37:H37) -> -274680.9 | I36: =SUM(I37:I37) -> -418035 | J36: =SUM(J37:J37) -> -429215.18 | ... Z36: =SUM(Z37:Z37) -> 0 | AA36: =SUM(C36,E36,G36,I36,K36,M36,O96,O36,Q36,S36,Y36,W36,U36) -> -4960042.8 | AB36: =D36+F36+H36+J36+L36+N36+P36+R36+T36+V36+X36+Z36 -> -2421309.1 | AC36: =IFERROR(AB36/AA36,0) -> 0.48816295
